<sdf version='1.7'>
  <model name='one_wheel'>
    <link name='base_link'>
      <inertial>
        <pose>0 0 0 0 -0 0</pose>
        <mass>8</mass>
        <inertia>
          <ixx>0.0666667</ixx>
          <ixy>0</ixy>
          <ixz>0</ixz>
          <iyy>0.173333</iyy>
          <iyz>0</iyz>
          <izz>0.173333</izz>
        </inertia>
      </inertial>
      <collision name='base_link_fixed_joint_lump__body_link_collision'>
        <pose>0 0 0 0 -0 0</pose>
        <geometry>
          <box>
            <size>0.5 0.3 0.1</size>
          </box>
        </geometry>
        <surface>
          <contact>
            <ode/>
          </contact>
          <friction>
            <ode/>
          </friction>
        </surface>
      </collision>
      <visual name='base_link_fixed_joint_lump__body_link_visual'>
        <pose>0 0 0 0 -0 0</pose>
        <geometry>
          <box>
            <size>0.5 0.3 0.1</size>
          </box>
        </geometry>
        <material>
          <script>
            <name>Gazebo/Wood</name>
            <uri>file://media/materials/scripts/gazebo.material</uri>
          </script>
        </material>
      </visual>
    </link>
    <joint name='bl_axle' type='revolute'>
      <pose relative_to='base_link'>0.3 -0.25 -0.1 1.57079 -0 0</pose>
      <parent>base_link</parent>
      <child>bl_1</child>
      <axis>
        <xyz>0 0 1</xyz>
        <limit>
          <effort>20</effort>
          <velocity>20</velocity>
          <lower>-1e+16</lower>
          <upper>1e+16</upper>
        </limit>
        <dynamics>
          <spring_reference>0</spring_reference>
          <spring_stiffness>0</spring_stiffness>
        </dynamics>
      </axis>
    </joint>
    <link name='bl_1'>
      <pose relative_to='bl_axle'>0 0 0 0 -0 0</pose>
      <inertial>
        <pose>0 0 0 0 -0 0</pose>
        <mass>0.3</mass>
        <inertia>
          <ixx>0.0008125</ixx>
          <ixy>0</ixy>
          <ixz>0</ixz>
          <iyy>0.0008125</iyy>
          <iyz>0</iyz>
          <izz>0.0015</izz>
        </inertia>
      </inertial>
      <collision name='bl_1_collision'>
        <pose>0 0 0 0 -0 0</pose>
        <geometry>
          <cylinder>
            <length>0.05</length>
            <radius>0.1</radius>
          </cylinder>
        </geometry>
        <surface>
          <contact>
            <ode>
              <kp>100000</kp>
              <kd>10</kd>
            </ode>
          </contact>
          <friction>
            <ode>
              <mu>1</mu>
              <mu2>1</mu2>
            </ode>
          </friction>
        </surface>
      </collision>
      <visual name='bl_1_visual'>
        <pose>0 0 0 0 -0 0</pose>
        <geometry>
          <cylinder>
            <length>0.05</length>
            <radius>0.1</radius>
          </cylinder>
        </geometry>
        <material>
          <script>
            <name>Gazebo/Black</name>
            <uri>file://media/materials/scripts/gazebo.material</uri>
          </script>
        </material>
      </visual>
      <self_collide>1</self_collide>
      <slip1>100</slip1>
    </link>
    <joint name='br_axle' type='revolute'>
      <pose relative_to='base_link'>0.3 0.25 -0.1 1.57079 -0 0</pose>
      <parent>base_link</parent>
      <child>br_1</child>
      <axis>
        <xyz>0 0 1</xyz>
        <limit>
          <effort>20</effort>
          <velocity>20</velocity>
          <lower>-1e+16</lower>
          <upper>1e+16</upper>
        </limit>
        <dynamics>
          <spring_reference>0</spring_reference>
          <spring_stiffness>0</spring_stiffness>
        </dynamics>
      </axis>
    </joint>
    <link name='br_1'>
      <pose relative_to='br_axle'>0 0 0 0 -0 0</pose>
      <inertial>
        <pose>0 0 0 0 -0 0</pose>
        <mass>0.3</mass>
        <inertia>
          <ixx>0.0008125</ixx>
          <ixy>0</ixy>
          <ixz>0</ixz>
          <iyy>0.0008125</iyy>
          <iyz>0</iyz>
          <izz>0.0015</izz>
        </inertia>
      </inertial>
      <collision name='br_1_collision'>
        <pose>0 0 0 0 -0 0</pose>
        <geometry>
          <cylinder>
            <length>0.05</length>
            <radius>0.1</radius>
          </cylinder>
        </geometry>
        <surface>
          <contact>
            <ode>
              <kp>100000</kp>
              <kd>10</kd>
            </ode>
          </contact>
          <friction>
            <ode>
              <mu>1</mu>
              <mu2>1</mu2>
            </ode>
          </friction>
        </surface>
      </collision>
      <visual name='br_1_visual'>
        <pose>0 0 0 0 -0 0</pose>
        <geometry>
          <cylinder>
            <length>0.05</length>
            <radius>0.1</radius>
          </cylinder>
        </geometry>
        <material>
          <script>
            <name>Gazebo/Black</name>
            <uri>file://media/materials/scripts/gazebo.material</uri>
          </script>
        </material>
      </visual>
      <self_collide>1</self_collide>
      <slip1>100</slip1>
    </link>
    <joint name='l_steer' type='revolute'>
      <pose relative_to='base_link'>-0.3 -0.25 -0.1 0 -0 0</pose>
      <parent>base_link</parent>
      <child>l_steer_1</child>
      <axis>
        <xyz>0 0 1</xyz>
        <limit>
          <lower>-0.95</lower>
          <upper>0.95</upper>
          <effort>100</effort>
          <velocity>100</velocity>
        </limit>
        <dynamics>
          <damping>0</damping>
          <friction>1</friction>
          <spring_reference>0</spring_reference>
          <spring_stiffness>0</spring_stiffness>
        </dynamics>
      </axis>
    </joint>
    <link name='l_steer_1'>
      <pose relative_to='l_steer'>0 0 0 0 -0 0</pose>
      <inertial>
        <pose>0.003381 0 0.02162 0 -0 0</pose>
        <mass>1</mass>
        <inertia>
          <ixx>1</ixx>
          <ixy>0</ixy>
          <ixz>0</ixz>
          <iyy>1</iyy>
          <iyz>0</iyz>
          <izz>1</izz>
        </inertia>
      </inertial>
      <visual name='l_steer_1_visual'>
        <pose>0 0 0 0 -0 0</pose>
        <geometry>
          <cylinder>
            <length>0.05</length>
            <radius>0.1</radius>
          </cylinder>
        </geometry>
        <material>
          <script>
            <name>Gazebo/GreyTransparent</name>
            <uri>file://media/materials/scripts/gazebo.material</uri>
          </script>
        </material>
      </visual>
      <self_collide>1</self_collide>
    </link>
    <joint name='fl_axle' type='revolute'>
      <pose relative_to='l_steer_1'>0 0 0 1.57079 -0 0</pose>
      <parent>l_steer_1</parent>
      <child>fl_1</child>
      <axis>
        <xyz>0 0 1</xyz>
        <limit>
          <effort>20</effort>
          <velocity>20</velocity>
          <lower>-1e+16</lower>
          <upper>1e+16</upper>
        </limit>
        <dynamics>
          <spring_reference>0</spring_reference>
          <spring_stiffness>0</spring_stiffness>
        </dynamics>
      </axis>
    </joint>
    <link name='fl_1'>
      <pose relative_to='fl_axle'>0 0 0 0 -0 0</pose>
      <inertial>
        <pose>0 0 0 0 -0 0</pose>
        <mass>0.3</mass>
        <inertia>
          <ixx>0.0008125</ixx>
          <ixy>0</ixy>
          <ixz>0</ixz>
          <iyy>0.0008125</iyy>
          <iyz>0</iyz>
          <izz>0.0015</izz>
        </inertia>
      </inertial>
      <collision name='fl_1_collision'>
        <pose>0 0 0 0 -0 0</pose>
        <geometry>
          <cylinder>
            <length>0.05</length>
            <radius>0.1</radius>
          </cylinder>
        </geometry>
        <surface>
          <contact>
            <ode>
              <kp>100000</kp>
              <kd>10</kd>
            </ode>
          </contact>
          <friction>
            <ode>
              <mu>1</mu>
              <mu2>1</mu2>
            </ode>
          </friction>
        </surface>
      </collision>
      <visual name='fl_1_visual'>
        <pose>0 0 0 0 -0 0</pose>
        <geometry>
          <cylinder>
            <length>0.05</length>
            <radius>0.1</radius>
          </cylinder>
        </geometry>
        <material>
          <script>
            <name>Gazebo/DarkGrey</name>
            <uri>file://media/materials/scripts/gazebo.material</uri>
          </script>
        </material>
      </visual>
      <self_collide>1</self_collide>
      <slip1>100</slip1>
    </link>
    <joint name='r_steer' type='revolute'>
      <pose relative_to='base_link'>-0.3 0.25 -0.1 0 -0 0</pose>
      <parent>base_link</parent>
      <child>r_steer_1</child>
      <axis>
        <xyz>0 0 1</xyz>
        <limit>
          <lower>-0.95</lower>
          <upper>0.95</upper>
          <effort>100</effort>
          <velocity>100</velocity>
        </limit>
        <dynamics>
          <damping>0</damping>
          <friction>1</friction>
          <spring_reference>0</spring_reference>
          <spring_stiffness>0</spring_stiffness>
        </dynamics>
      </axis>
    </joint>
    <link name='r_steer_1'>
      <pose relative_to='r_steer'>0 0 0 0 -0 0</pose>
      <inertial>
        <pose>0.003381 0 0.02162 0 -0 0</pose>
        <mass>1</mass>
        <inertia>
          <ixx>1</ixx>
          <ixy>0</ixy>
          <ixz>0</ixz>
          <iyy>1</iyy>
          <iyz>0</iyz>
          <izz>1</izz>
        </inertia>
      </inertial>
      <visual name='r_steer_1_visual'>
        <pose>0 0 0 0 -0 0</pose>
        <geometry>
          <cylinder>
            <length>0.05</length>
            <radius>0.1</radius>
          </cylinder>
        </geometry>
        <material>
          <script>
            <name>Gazebo/GreyTransparent</name>
            <uri>file://media/materials/scripts/gazebo.material</uri>
          </script>
        </material>
      </visual>
      <self_collide>1</self_collide>
    </link>
    <joint name='fr_axle' type='revolute'>
      <pose relative_to='r_steer_1'>0 0 0 1.57079 -0 0</pose>
      <parent>r_steer_1</parent>
      <child>fr_1</child>
      <axis>
        <xyz>0 0 1</xyz>
        <limit>
          <effort>20</effort>
          <velocity>20</velocity>
          <lower>-1e+16</lower>
          <upper>1e+16</upper>
        </limit>
        <dynamics>
          <spring_reference>0</spring_reference>
          <spring_stiffness>0</spring_stiffness>
        </dynamics>
      </axis>
    </joint>
    <link name='fr_1'>
      <pose relative_to='fr_axle'>0 0 0 0 -0 0</pose>
      <inertial>
        <pose>0 0 0 0 -0 0</pose>
        <mass>0.3</mass>
        <inertia>
          <ixx>0.0008125</ixx>
          <ixy>0</ixy>
          <ixz>0</ixz>
          <iyy>0.0008125</iyy>
          <iyz>0</iyz>
          <izz>0.0015</izz>
        </inertia>
      </inertial>
      <collision name='fr_1_collision'>
        <pose>0 0 0 0 -0 0</pose>
        <geometry>
          <cylinder>
            <length>0.05</length>
            <radius>0.1</radius>
          </cylinder>
        </geometry>
        <surface>
          <contact>
            <ode>
              <kp>100000</kp>
              <kd>10</kd>
            </ode>
          </contact>
          <friction>
            <ode>
              <mu>1</mu>
              <mu2>1</mu2>
            </ode>
          </friction>
        </surface>
      </collision>
      <visual name='fr_1_visual'>
        <pose>0 0 0 0 -0 0</pose>
        <geometry>
          <cylinder>
            <length>0.05</length>
            <radius>0.1</radius>
          </cylinder>
        </geometry>
        <material>
          <script>
            <name>Gazebo/DarkGrey</name>
            <uri>file://media/materials/scripts/gazebo.material</uri>
          </script>
        </material>
      </visual>
      <self_collide>1</self_collide>
      <slip1>100</slip1>
    </link>
    <joint name='steering_joint' type='revolute'>
      <pose relative_to='base_link'>0 0 0.056 0 -0 0</pose>
      <parent>base_link</parent>
      <child>steering_wheel</child>
      <axis>
        <xyz>0 0 1</xyz>
        <limit>
          <effort>100</effort>
          <velocity>100</velocity>
          <lower>-1e+16</lower>
          <upper>1e+16</upper>
        </limit>
        <dynamics>
          <damping>0</damping>
          <friction>1</friction>
          <spring_reference>0</spring_reference>
          <spring_stiffness>0</spring_stiffness>
        </dynamics>
      </axis>
    </joint>
    <link name='steering_wheel'>
      <pose relative_to='steering_joint'>0 0 0 0 -0 0</pose>
      <inertial>
        <pose>0 0 0 0 -0 0</pose>
        <mass>0.8</mass>
        <inertia>
          <ixx>2.66667e-05</ixx>
          <ixy>0</ixy>
          <ixz>0</ixz>
          <iyy>2.66667e-05</iyy>
          <iyz>0</iyz>
          <izz>4e-05</izz>
        </inertia>
      </inertial>
      <visual name='steering_wheel_visual'>
        <pose>0 0 0 0 -0 0</pose>
        <geometry>
          <cylinder>
            <length>0.01</length>
            <radius>0.01</radius>
          </cylinder>
        </geometry>
      </visual>
    </link>
    <static>0</static>
    <plugin name='ackermann_drive' filename='libgazebo_ros_ackermann_drive.so'>
      <ros>
        <namespace>ackermann_dorothy</namespace>
        <remapping>cmd_vel:=cmd_vel</remapping>
        <remapping>odom:=odom</remapping>
        <remapping>distance:=distance</remapping>
      </ros>
      <update_rate>100.0</update_rate>
      <front_left_joint>fl_axle</front_left_joint>
      <front_right_joint>fr_axle</front_right_joint>
      <rear_left_joint>bl_axle</rear_left_joint>
      <rear_right_joint>br_axle</rear_right_joint>
      <left_steering_joint>l_steer</left_steering_joint>
      <right_steering_joint>r_steer</right_steering_joint>
      <max_steer>0.6</max_steer>
      <max_steering_angle>2</max_steering_angle>
      <max_speed>10</max_speed>
      <left_steering_pid_gain>100 0 17</left_steering_pid_gain>
      <left_steering_i_range>0 0</left_steering_i_range>
      <right_steering_pid_gain>100 0 17</right_steering_pid_gain>
      <right_steering_i_range>0 0</right_steering_i_range>
      <linear_velocity_pid_gain>1 0 0</linear_velocity_pid_gain>
      <linear_velocity_i_range>0 0</linear_velocity_i_range>
      <publish_odom>1</publish_odom>
      <publish_odom_tf>1</publish_odom_tf>
      <publish_wheel_tf>1</publish_wheel_tf>
      <publish_distance>1</publish_distance>
      <odometry_frame>odom</odometry_frame>
      <robot_base_frame>base_link</robot_base_frame>
    </plugin>
  </model>
</sdf>
