<?xml version="1.0"?>
<!-- Macros and impelemnatation of wheels, suspensions and steering system -->

<robot xmlns:xacro="http://ros.org/wiki/xacro">
    <material name="Wheel_Black">
        <color rgba="0.1 0.1 0.1 1" />
    </material>
    <xacro:property name="w_wheel" value="0.05" />
    <xacro:property name="r_wheel" value="0.1" />
    <xacro:property name="m_wheel" value="0.3" />
    <xacro:property name="M_PI" value="3.14159265359" />

    <xacro:property name="fdir" value="0 0 1"/>
    <xacro:property name="kd" value="1e1" />
    <xacro:property name="kp" value="1e5" />
    <xacro:property name="wheel_slip" value="100" />
    <xacro:property name="wheel_mu1" value="1.0" />
    <xacro:property name="wheel_mu2" value="1.0" />

    <xacro:property name="wheel_max_effort" value="20.0" />
    <xacro:property name="wheel_max_velocity" value="20.0" />

    <xacro:macro name="cylinder_inertia" params="m r h">
        <inertial>
            <origin xyz="0 0 0" rpy="0 0 0"/>
            <mass value="${m}" />
            <inertia ixx="${m*(3*r*r+h*h)/12}" ixy="0" ixz="0" iyy="${m*(3*r*r+h*h)/12}" iyz="0" izz="${m*r*r/2}" />
        </inertial>
    </xacro:macro>
    <xacro:macro name="wheel_link" params="name">

        <link name="${name}_1">
            <xacro:cylinder_inertia m="${m_wheel}" r="${r_wheel}" h="${w_wheel}"/>
            <visual>
                <origin rpy="0 0 0" xyz="0 0 0"/>
                <geometry>
                    <cylinder radius="${r_wheel}" length="${w_wheel}" />
                </geometry>
                <material name="Wheel_Black"/>
            </visual>
            <collision>
                <origin rpy="0 0 0" xyz="0 0 0"/>
                <geometry>
                    <cylinder radius="${r_wheel}" length="${w_wheel}" />
                </geometry>
            </collision>
        </link>
    </xacro:macro>

    <xacro:macro name="autocar_back_wheel" params="name rpy xyz base_link_name">
        <xacro:wheel_link name="${name}"/>

        <joint name="${name}_axle" type="continuous">
            <origin rpy="${M_PI/2} 0 0" xyz="${xyz}"/>
            <parent link="${base_link_name}"/>
            <child link="${name}_1"/>
            <axis xyz="0.0 0.0 1.0"/>
            <limit effort="${wheel_max_effort}"  velocity="${wheel_max_velocity}"/>
        </joint>
        <gazebo reference="${name}_1">
            <material value="Gazebo/Black"/>

            <mu1>${wheel_mu1}</mu1>
            <mu2>${wheel_mu2}</mu2>
            <slip1>${wheel_slip}</slip1>
            <!-- <fdir1>${fdir}</fdir1> -->
            <kp>${kp}</kp>
            <kd>${kd}</kd>
            <selfCollide>true</selfCollide>
        </gazebo>
    </xacro:macro>

    <xacro:macro name="autocar_front_wheel" params="name steer_name rpy xyz base_link_name">

        <xacro:wheel_link name="${name}"/>
        <link name="${steer_name}_1">
            <inertial>
                <origin rpy="0 0 0" xyz="0.003381 1.5929e-07 0.02162"/>
                <mass value="1"/>
                <inertia ixx="1.0" ixy="0.0" ixz="0.0" iyy="1.0" iyz="0.0" izz="1.0"/>
            </inertial>
            <visual>
                <origin rpy="0 0 0" xyz="0 0 0"/>
                <geometry>
                    <cylinder radius="${r_wheel}" length="${w_wheel}" />
                </geometry>
                <material name="Wheel_Black"/>
            </visual>
        </link>

        <joint name="${steer_name}" type="revolute">
            <origin rpy="0 0 0" xyz="${xyz}"/>
            <parent link="${base_link_name}"/>
            <child link="${steer_name}_1"/>
            <axis xyz="0.0 0.0 1.0"/>
            <dynamics damping="0.0" friction="1.0"/>
            <limit effort="100.0" lower="-0.95" upper="0.95" velocity="100"/>
        </joint>
        <joint name="${name}_axle" type="continuous">
            <origin rpy="${M_PI/2} 0 0" xyz="0.0 0.0 0.0"/>
            <parent link="${steer_name}_1"/>
            <child link="${name}_1"/>
            <axis xyz="0.0 0.0 1.0"/>
            <limit effort="${wheel_max_effort}"  velocity="${wheel_max_velocity}"/>
        </joint>

        <gazebo reference="${steer_name}_1">
            <material value="Gazebo/GreyTransparent " />
            <mu1>0.2</mu1>
            <mu2>0.2</mu2>
            <selfCollide>true</selfCollide>
        </gazebo>
        <gazebo reference="${name}_1">
            <material>Gazebo/DarkGrey</material>
            <mu1>${wheel_mu1}</mu1>
            <mu2>${wheel_mu1}</mu2>
            <slip1>${wheel_slip}</slip1>
            <!-- <fdir1>${fdir}</fdir1> -->
            <kp>${kp}</kp>
            <kd>${kd}</kd>
            <selfCollide>true</selfCollide>
        </gazebo>
    </xacro:macro>

</robot>