<?xml version="1.0" ?>
<!-- =================================================================================== -->
<!-- |    This document was autogenerated by xacro from dorothy_ackermann.xacro        | -->
<!-- |    EDITING THIS FILE BY HAND IS NOT RECOMMENDED                                 | -->
<!-- =================================================================================== -->
<robot name="dorothy">
  <material name="blue">
    <color rgba="0 0 .7 1"/>
  </material>
  <material name="red">
    <color rgba="0.7 0 0 1"/>
  </material>
  <link name="pod">
    <visual>
      <origin rpy="0 0 0" xyz="0 0 0.0"/>
      <geometry>
        <box size="0.4 0.2 0.1"/>
      </geometry>
      <material name="blue"/>
    </visual>
    <collision>
      <geometry>
        <box size="0.4 0.2 0.1"/>
      </geometry>
    </collision>
    <inertial>
      <mass value="0.1"/>
      <origin xyz="0 0 0"/>
      <inertia ixx="0.001" ixy="0.0" ixz="0.0" iyy="0.001" iyz="0.0" izz="0.001"/>
    </inertial>
  </link>
  <!--_LIDAR -->
  <link name="laser">
    <visual>
      <origin rpy="0 0 0" xyz="0 0 0.0"/>
      <geometry>
        <cylinder length="0.0315" radius="0.055"/>
      </geometry>
      <material name="red"/>
    </visual>
    <collision>
      <origin rpy="0 0 0" xyz="0.015 0 -0.0065"/>
      <geometry>
        <cylinder length="0.0315" radius="0.055"/>
      </geometry>
    </collision>
    <inertial>
      <mass value="0.114"/>
      <origin xyz="0 0 0"/>
      <inertia ixx="0.001" ixy="0.0" ixz="0.0" iyy="0.001" iyz="0.0" izz="0.001"/>
    </inertial>
  </link>
  <gazebo reference="laser">
    <material>Gazebo/FlatBlack</material>
    <sensor name="lidar_sensor" type="ray">
      <pose>0 0 0 0 0 0</pose>
      <visualize>false</visualize>
      <update_rate>15</update_rate>
      <ray>
        <scan>
          <horizontal>
            <samples>360</samples>
            <resolution>1</resolution>
            <min_angle>0.0</min_angle>
            <max_angle>6.28319</max_angle>
          </horizontal>
        </scan>
        <range>
          <min>0.120</min>
          <max>10.0</max>
          <resolution>0.050</resolution>
        </range>
        <noise>
          <type>gaussian</type>
          <mean>0.0</mean>
          <stddev>0.01</stddev>
        </noise>
      </ray>
      <plugin filename="libgazebo_ros_ray_sensor.so" name="scan">
        <ros>
          <remapping>~/out:=scan</remapping>
        </ros>
        <output_type>sensor_msgs/LaserScan</output_type>
        <frame_name>laser</frame_name>
      </plugin>
    </sensor>
  </gazebo>
  <joint name="scan_joint" type="fixed">
    <parent link="pod"/>
    <child link="laser"/>
    <origin rpy="0 0 3.14" xyz="0 0 0.15"/>
  </joint>
  <gazebo reference="scan_joint">
    <preserveFixedJoint>true</preserveFixedJoint>
    <!-- <disableFixedJointLumping>true</disableFixedJointLumping> -->
  </gazebo>
  <!-- IMU -->
  <link name="imu">
    <visual>
      <origin rpy="0 0 0" xyz="0 0 0.0"/>
      <geometry>
        <box size="0.03 0.03 0.03"/>
      </geometry>
      <material name="red"/>
    </visual>
    <collision>
      <origin rpy="0 0 0" xyz="0 0 0"/>
      <geometry>
        <box height="0.03" length="0.03" width="0.03"/>
      </geometry>
    </collision>
    <inertial>
      <mass value="0.114"/>
      <origin xyz="0 0 0"/>
      <inertia ixx="0.001" ixy="0.0" ixz="0.0" iyy="0.001" iyz="0.0" izz="0.001"/>
    </inertial>
  </link>
  <gazebo reference="imu">
    <material>Gazebo/FlatBlack</material>
    <sensor name="my_imu" type="imu">
      <always_on>true</always_on>
      <!-- Publish at 30 hz -->
      <update_rate>30</update_rate>
      <plugin filename="libgazebo_ros_imu_sensor.so" name="my_imu_plugin">
        <ros>
          <!-- Will publish to /imu/data -->
          <namespace>/imu</namespace>
          <remapping>~/out:=data</remapping>
        </ros>
        <!-- frame_name ommited, will be "my_link" -->
      </plugin>
    </sensor>
  </gazebo>
  <joint name="imu_joint" type="fixed">
    <parent link="pod"/>
    <child link="imu"/>
    <origin rpy="0 0 3.14" xyz="0.185 0 0.065"/>
  </joint>
  <gazebo reference="imu_joint">
    <preserveFixedJoint>true</preserveFixedJoint>
    <!-- <disableFixedJointLumping>true</disableFixedJointLumping> -->
  </gazebo>
  <link name="camera_front">
    <visual>
      <origin rpy="0 0 0" xyz="0 0 0.0"/>
      <geometry>
        <box size="0.01 0.04 0.04"/>
      </geometry>
      <material name="red"/>
    </visual>
    <collision>
      <geometry>
        <box size="0.01 0.04 0.04"/>
      </geometry>
    </collision>
    <inertial>
      <mass value="0.01"/>
      <origin xyz="0 0 0"/>
      <inertia ixx="0.0001" ixy="0.0" ixz="0.0" iyy="0.0001" iyz="0.0" izz="0.0001"/>
    </inertial>
  </link>
  <gazebo reference="camera_front">
    <material>Gazebo/Red</material>
    <sensor name="camera_front_sensor" type="camera">
      <!-- <pose>-3 -1 1.4 0 0.37 0</pose> -->
      <camera>
        <horizontal_fov>1.5</horizontal_fov>
        <image>
          <width>640</width>
          <height>480</height>
        </image>
        <clip>
          <near>0.1</near>
          <far>1000</far>
        </clip>
      </camera>
      <always_on>1</always_on>
      <update_rate>10</update_rate>
      <visualize>false</visualize>
      <!-- <format>L8</format> -->
      <camera name="camera_front">
        <distortion>
          <k1>0.0</k1>
          <k2>0.0</k2>
          <k3>0.0</k3>
          <p1>0.0</p1>
          <p2>0.0</p2>
          <center> 0.5 0.5 </center>
        </distortion>
      </camera>
      <plugin filename="libgazebo_ros_camera.so" name="camera_controller">
        <ros>
          <namespace/>
        </ros>
        <hack_baseline>0.07</hack_baseline>
        <frame_name>camera_front</frame_name>
      </plugin>
    </sensor>
  </gazebo>
  <joint name="cam_joint_front" type="fixed">
    <parent link="pod"/>
    <child link="camera_front"/>
    <origin rpy="0 0 0" xyz="0.3 0.0 0.0"/>
  </joint>
  <gazebo reference="cam_joint_front">
    <preserveFixedJoint>true</preserveFixedJoint>
    <!-- <disableFixedJointLumping>true</disableFixedJointLumping> -->
  </gazebo>
  <link name="camera_right">
    <visual>
      <origin rpy="0 0 0" xyz="0 0 0.0"/>
      <geometry>
        <box size="0.01 0.04 0.04"/>
      </geometry>
      <material name="red"/>
    </visual>
    <collision>
      <geometry>
        <box size="0.01 0.04 0.04"/>
      </geometry>
    </collision>
    <inertial>
      <mass value="0.01"/>
      <origin xyz="0 0 0"/>
      <inertia ixx="0.0001" ixy="0.0" ixz="0.0" iyy="0.0001" iyz="0.0" izz="0.0001"/>
    </inertial>
  </link>
  <gazebo reference="camera_right">
    <material>Gazebo/Red</material>
    <sensor name="camera_right_sensor" type="camera">
      <!-- <pose>-3 -1 1.4 0 0.37 0</pose> -->
      <camera>
        <horizontal_fov>1.5</horizontal_fov>
        <image>
          <width>640</width>
          <height>480</height>
        </image>
        <clip>
          <near>0.1</near>
          <far>1000</far>
        </clip>
      </camera>
      <always_on>1</always_on>
      <update_rate>10</update_rate>
      <visualize>false</visualize>
      <!-- <format>L8</format> -->
      <camera name="camera_right">
        <distortion>
          <k1>0.0</k1>
          <k2>0.0</k2>
          <k3>0.0</k3>
          <p1>0.0</p1>
          <p2>0.0</p2>
          <center> 0.5 0.5 </center>
        </distortion>
      </camera>
      <plugin filename="libgazebo_ros_camera.so" name="camera_controller">
        <ros>
          <namespace/>
        </ros>
        <hack_baseline>0.07</hack_baseline>
        <frame_name>camera_right</frame_name>
      </plugin>
    </sensor>
  </gazebo>
  <joint name="cam_joint_right" type="fixed">
    <parent link="pod"/>
    <child link="camera_right"/>
    <origin rpy="0 0 -0.6283179999999999" xyz="-0.1 -0.12 0.05"/>
  </joint>
  <gazebo reference="cam_joint_right">
    <preserveFixedJoint>true</preserveFixedJoint>
    <!-- <disableFixedJointLumping>true</disableFixedJointLumping> -->
  </gazebo>
  <link name="camera_left">
    <visual>
      <origin rpy="0 0 0" xyz="0 0 0.0"/>
      <geometry>
        <box size="0.01 0.04 0.04"/>
      </geometry>
      <material name="red"/>
    </visual>
    <collision>
      <geometry>
        <box size="0.01 0.04 0.04"/>
      </geometry>
    </collision>
    <inertial>
      <mass value="0.01"/>
      <origin xyz="0 0 0"/>
      <inertia ixx="0.0001" ixy="0.0" ixz="0.0" iyy="0.0001" iyz="0.0" izz="0.0001"/>
    </inertial>
  </link>
  <gazebo reference="camera_left">
    <material>Gazebo/Red</material>
    <sensor name="camera_left_sensor" type="camera">
      <!-- <pose>-3 -1 1.4 0 0.37 0</pose> -->
      <camera>
        <horizontal_fov>1.5</horizontal_fov>
        <image>
          <width>640</width>
          <height>480</height>
        </image>
        <clip>
          <near>0.1</near>
          <far>1000</far>
        </clip>
      </camera>
      <always_on>1</always_on>
      <update_rate>10</update_rate>
      <visualize>false</visualize>
      <!-- <format>L8</format> -->
      <camera name="camera_left">
        <distortion>
          <k1>0.0</k1>
          <k2>0.0</k2>
          <k3>0.0</k3>
          <p1>0.0</p1>
          <p2>0.0</p2>
          <center> 0.5 0.5 </center>
        </distortion>
      </camera>
      <plugin filename="libgazebo_ros_camera.so" name="camera_controller">
        <ros>
          <namespace/>
        </ros>
        <hack_baseline>0.07</hack_baseline>
        <frame_name>camera_left</frame_name>
      </plugin>
    </sensor>
  </gazebo>
  <joint name="cam_joint_left" type="fixed">
    <parent link="pod"/>
    <child link="camera_left"/>
    <origin rpy="0 0 0.6283179999999999" xyz="-0.1 0.12 0.05"/>
  </joint>
  <gazebo reference="cam_joint_left">
    <preserveFixedJoint>true</preserveFixedJoint>
    <!-- <disableFixedJointLumping>true</disableFixedJointLumping> -->
  </gazebo>
  <link name="camera_rear">
    <visual>
      <origin rpy="0 0 0" xyz="0 0 0.0"/>
      <geometry>
        <box size="0.01 0.04 0.04"/>
      </geometry>
      <material name="red"/>
    </visual>
    <collision>
      <geometry>
        <box size="0.01 0.04 0.04"/>
      </geometry>
    </collision>
    <inertial>
      <mass value="0.01"/>
      <origin xyz="0 0 0"/>
      <inertia ixx="0.0001" ixy="0.0" ixz="0.0" iyy="0.0001" iyz="0.0" izz="0.0001"/>
    </inertial>
  </link>
  <gazebo reference="camera_rear">
    <material>Gazebo/Red</material>
    <sensor name="camera_rear_sensor" type="camera">
      <!-- <pose>-3 -1 1.4 0 0.37 0</pose> -->
      <camera>
        <horizontal_fov>1.5</horizontal_fov>
        <image>
          <width>640</width>
          <height>480</height>
        </image>
        <clip>
          <near>0.1</near>
          <far>1000</far>
        </clip>
      </camera>
      <always_on>1</always_on>
      <update_rate>10</update_rate>
      <visualize>false</visualize>
      <!-- <format>L8</format> -->
      <camera name="camera_rear">
        <distortion>
          <k1>0.0</k1>
          <k2>0.0</k2>
          <k3>0.0</k3>
          <p1>0.0</p1>
          <p2>0.0</p2>
          <center> 0.5 0.5 </center>
        </distortion>
      </camera>
      <plugin filename="libgazebo_ros_camera.so" name="camera_controller">
        <ros>
          <namespace/>
        </ros>
        <hack_baseline>0.07</hack_baseline>
        <frame_name>camera_rear</frame_name>
      </plugin>
    </sensor>
  </gazebo>
  <joint name="cam_joint_rear" type="fixed">
    <parent link="pod"/>
    <child link="camera_rear"/>
    <origin rpy="0 0 3.14159" xyz="-0.3 0.0 0.0"/>
  </joint>
  <gazebo reference="cam_joint_rear">
    <preserveFixedJoint>true</preserveFixedJoint>
    <!-- <disableFixedJointLumping>true</disableFixedJointLumping> -->
  </gazebo>
  <material name="Wheel_Black">
    <color rgba="0.1 0.1 0.1 1"/>
  </material>
  <link name="base_link">
    <visual>
      <geometry>
        <box size="0.5 0.3 0.1"/>
      </geometry>
      <material name="Body_Gray"/>
    </visual>
    <collision>
      <geometry>
        <box size="0.5 0.3 0.1"/>
      </geometry>
    </collision>
    <inertial>
      <mass value="8"/>
      <inertia ixx="0.06666666666666667" ixy="0" ixz="0" iyy="0.17333333333333334" iyz="0" izz="0.17333333333333334"/>
    </inertial>
  </link>
  <joint name="pod_joint" type="fixed">
    <parent link="base_link"/>
    <child link="pod"/>
    <origin rpy="0 0 3.14159265359" xyz="0 0 0.1"/>
  </joint>
  <gazebo reference="pod_joint">
    <preserveFixedJoint>true</preserveFixedJoint>
    <!-- <disableFixedJointLumping>true</disableFixedJointLumping> -->
  </gazebo>
  <link name="base_footprint">
    <visual>
      <geometry>
        <box size="0.25 0.15 0.05"/>
      </geometry>
      <material name="Body_Gray"/>
    </visual>
    <inertial>
      <mass value="1.0"/>
      <inertia ixx="0.0020833333333333333" ixy="0" ixz="0" iyy="0.005416666666666667" iyz="0" izz="0.005416666666666667"/>
    </inertial>
  </link>
  <!-- The base footprint of the robot is located underneath the chassis -->
  <joint name="footprint_joint" type="fixed">
    <parent link="base_footprint"/>
    <child link="base_link"/>
    <origin rpy="0 0 3.14159265359" xyz="0 0 0.2"/>
  </joint>
  <gazebo reference="footprint_joint">
    <preserveFixedJoint>true</preserveFixedJoint>
    <!-- <disableFixedJointLumping>true</disableFixedJointLumping> -->
  </gazebo>
  <gazebo reference="base_footprint">
    <material value="Gazebo/Wood"/>
  </gazebo>
  <gazebo reference="base_link">
    <material value="Gazebo/Wood"/>
  </gazebo>
  <link name="fr_1">
    <inertial>
      <origin rpy="0 0 0" xyz="0 0 0"/>
      <mass value="0.3"/>
      <inertia ixx="0.0008125000000000002" ixy="0" ixz="0" iyy="0.0008125000000000002" iyz="0" izz="0.0015"/>
    </inertial>
    <visual>
      <origin rpy="0 0 0" xyz="0 0 0"/>
      <geometry>
        <cylinder length="0.05" radius="0.1"/>
      </geometry>
      <material name="Wheel_Black"/>
    </visual>
    <collision>
      <origin rpy="0 0 0" xyz="0 0 0"/>
      <geometry>
        <cylinder length="0.05" radius="0.1"/>
      </geometry>
    </collision>
  </link>
  <link name="r_steer_1">
    <inertial>
      <origin rpy="0 0 0" xyz="0.003381 1.5929e-07 0.02162"/>
      <mass value="1"/>
      <inertia ixx="1.0" ixy="0.0" ixz="0.0" iyy="1.0" iyz="0.0" izz="1.0"/>
    </inertial>
    <visual>
      <origin rpy="0 0 0" xyz="0 0 0"/>
      <geometry>
        <cylinder length="0.05" radius="0.1"/>
      </geometry>
      <material name="Wheel_Black"/>
    </visual>
  </link>
  <joint name="r_steer" type="revolute">
    <origin rpy="0 0 0" xyz="-0.3 0.25 -0.1"/>
    <parent link="base_link"/>
    <child link="r_steer_1"/>
    <axis xyz="0.0 0.0 1.0"/>
    <dynamics damping="0.0" friction="1.0"/>
    <limit effort="100.0" lower="-0.95" upper="0.95" velocity="100"/>
  </joint>
  <joint name="fr_axle" type="continuous">
    <origin rpy="1.570796326795 0 0" xyz="0.0 0.0 0.0"/>
    <parent link="r_steer_1"/>
    <child link="fr_1"/>
    <axis xyz="0.0 0.0 1.0"/>
    <limit effort="20.0" velocity="20.0"/>
  </joint>
  <gazebo reference="r_steer_1">
    <material value="Gazebo/GreyTransparent "/>
    <mu1>0.2</mu1>
    <mu2>0.2</mu2>
    <selfCollide>true</selfCollide>
  </gazebo>
  <gazebo reference="fr_1">
    <material>Gazebo/DarkGrey</material>
    <mu1>1.0</mu1>
    <mu2>1.0</mu2>
    <slip1>100</slip1>
    <!-- <fdir1>${fdir}</fdir1> -->
    <kp>100000.0</kp>
    <kd>10.0</kd>
    <selfCollide>true</selfCollide>
  </gazebo>
  <link name="fl_1">
    <inertial>
      <origin rpy="0 0 0" xyz="0 0 0"/>
      <mass value="0.3"/>
      <inertia ixx="0.0008125000000000002" ixy="0" ixz="0" iyy="0.0008125000000000002" iyz="0" izz="0.0015"/>
    </inertial>
    <visual>
      <origin rpy="0 0 0" xyz="0 0 0"/>
      <geometry>
        <cylinder length="0.05" radius="0.1"/>
      </geometry>
      <material name="Wheel_Black"/>
    </visual>
    <collision>
      <origin rpy="0 0 0" xyz="0 0 0"/>
      <geometry>
        <cylinder length="0.05" radius="0.1"/>
      </geometry>
    </collision>
  </link>
  <link name="l_steer_1">
    <inertial>
      <origin rpy="0 0 0" xyz="0.003381 1.5929e-07 0.02162"/>
      <mass value="1"/>
      <inertia ixx="1.0" ixy="0.0" ixz="0.0" iyy="1.0" iyz="0.0" izz="1.0"/>
    </inertial>
    <visual>
      <origin rpy="0 0 0" xyz="0 0 0"/>
      <geometry>
        <cylinder length="0.05" radius="0.1"/>
      </geometry>
      <material name="Wheel_Black"/>
    </visual>
  </link>
  <joint name="l_steer" type="revolute">
    <origin rpy="0 0 0" xyz="-0.3 -0.25  -0.1"/>
    <parent link="base_link"/>
    <child link="l_steer_1"/>
    <axis xyz="0.0 0.0 1.0"/>
    <dynamics damping="0.0" friction="1.0"/>
    <limit effort="100.0" lower="-0.95" upper="0.95" velocity="100"/>
  </joint>
  <joint name="fl_axle" type="continuous">
    <origin rpy="1.570796326795 0 0" xyz="0.0 0.0 0.0"/>
    <parent link="l_steer_1"/>
    <child link="fl_1"/>
    <axis xyz="0.0 0.0 1.0"/>
    <limit effort="20.0" velocity="20.0"/>
  </joint>
  <gazebo reference="l_steer_1">
    <material value="Gazebo/GreyTransparent "/>
    <mu1>0.2</mu1>
    <mu2>0.2</mu2>
    <selfCollide>true</selfCollide>
  </gazebo>
  <gazebo reference="fl_1">
    <material>Gazebo/DarkGrey</material>
    <mu1>1.0</mu1>
    <mu2>1.0</mu2>
    <slip1>100</slip1>
    <!-- <fdir1>${fdir}</fdir1> -->
    <kp>100000.0</kp>
    <kd>10.0</kd>
    <selfCollide>true</selfCollide>
  </gazebo>
  <link name="br_1">
    <inertial>
      <origin rpy="0 0 0" xyz="0 0 0"/>
      <mass value="0.3"/>
      <inertia ixx="0.0008125000000000002" ixy="0" ixz="0" iyy="0.0008125000000000002" iyz="0" izz="0.0015"/>
    </inertial>
    <visual>
      <origin rpy="0 0 0" xyz="0 0 0"/>
      <geometry>
        <cylinder length="0.05" radius="0.1"/>
      </geometry>
      <material name="Wheel_Black"/>
    </visual>
    <collision>
      <origin rpy="0 0 0" xyz="0 0 0"/>
      <geometry>
        <cylinder length="0.05" radius="0.1"/>
      </geometry>
    </collision>
  </link>
  <joint name="br_axle" type="continuous">
    <origin rpy="1.570796326795 0 0" xyz="0.3 0.25 -0.1"/>
    <parent link="base_link"/>
    <child link="br_1"/>
    <axis xyz="0.0 0.0 1.0"/>
    <limit effort="20.0" velocity="20.0"/>
  </joint>
  <gazebo reference="br_1">
    <material value="Gazebo/Black"/>
    <mu1>1.0</mu1>
    <mu2>1.0</mu2>
    <slip1>100</slip1>
    <!-- <fdir1>${fdir}</fdir1> -->
    <kp>100000.0</kp>
    <kd>10.0</kd>
    <selfCollide>true</selfCollide>
  </gazebo>
  <link name="bl_1">
    <inertial>
      <origin rpy="0 0 0" xyz="0 0 0"/>
      <mass value="0.3"/>
      <inertia ixx="0.0008125000000000002" ixy="0" ixz="0" iyy="0.0008125000000000002" iyz="0" izz="0.0015"/>
    </inertial>
    <visual>
      <origin rpy="0 0 0" xyz="0 0 0"/>
      <geometry>
        <cylinder length="0.05" radius="0.1"/>
      </geometry>
      <material name="Wheel_Black"/>
    </visual>
    <collision>
      <origin rpy="0 0 0" xyz="0 0 0"/>
      <geometry>
        <cylinder length="0.05" radius="0.1"/>
      </geometry>
    </collision>
  </link>
  <joint name="bl_axle" type="continuous">
    <origin rpy="1.570796326795 0 0" xyz="0.3 -0.25 -0.1"/>
    <parent link="base_link"/>
    <child link="bl_1"/>
    <axis xyz="0.0 0.0 1.0"/>
    <limit effort="20.0" velocity="20.0"/>
  </joint>
  <gazebo reference="bl_1">
    <material value="Gazebo/Black"/>
    <mu1>1.0</mu1>
    <mu2>1.0</mu2>
    <slip1>100</slip1>
    <!-- <fdir1>${fdir}</fdir1> -->
    <kp>100000.0</kp>
    <kd>10.0</kd>
    <selfCollide>true</selfCollide>
  </gazebo>
  <gazebo>
    <plugin filename="libgazebo_ros_ackermann_drive.so" name="ackermann_drive">
      <ros>
        <!-- <namespace>ackermann_dorothy</namespace> -->
        <remapping>cmd_vel:=cmd_vel</remapping>
        <remapping>odom:=wheel/odometry</remapping>
        <remapping>distance:=distance</remapping>
      </ros>
      <update_rate>60.0</update_rate>
      <!-- wheels -->
      <front_left_joint>fl_axle</front_left_joint>
      <front_right_joint>fr_axle</front_right_joint>
      <rear_left_joint>bl_axle</rear_left_joint>
      <rear_right_joint>br_axle</rear_right_joint>
      <left_steering_joint>l_steer</left_steering_joint>
      <right_steering_joint>r_steer</right_steering_joint>
      <!-- <steering_wheel_joint>steering_joint</steering_wheel_joint> -->
      <!-- Max absolute steer angle for tyre in radians-->
      <!-- Any cmd_vel angular z greater than this would be capped -->
      <max_steer>0.6</max_steer>
      <!-- Max absolute steering angle of steering wheel -->
      <!-- Max absolute steering angle of steering wheel -->
      <max_steering_angle>2</max_steering_angle>
      <!-- Max absolute linear speed in m/s -->
      <max_speed>10</max_speed>
      <!-- PID tuning -->
      <left_steering_pid_gain>100 0 17 </left_steering_pid_gain>
      <left_steering_i_range>0 0</left_steering_i_range>
      <right_steering_pid_gain>100 0 17</right_steering_pid_gain>
      <right_steering_i_range>0 0</right_steering_i_range>
      <linear_velocity_pid_gain>1 0 0</linear_velocity_pid_gain>
      <linear_velocity_i_range>0 0</linear_velocity_i_range>
      <!-- output -->
      <publish_odom>true</publish_odom>
      <publish_odom_tf>false</publish_odom_tf>
      <publish_wheel_tf>false</publish_wheel_tf>
      <publish_distance>false</publish_distance>
      <odometry_frame>odom</odometry_frame>
      <robot_base_frame>base_footprint</robot_base_frame>
    </plugin>
  </gazebo>
  <gazebo>
    <plugin filename="libgazebo_ros_joint_state_publisher.so" name="dorothy2_joint_state">
      <ros>
        <remapping>~/out:=joint_states</remapping>
      </ros>
      <update_rate>30</update_rate>
      <joint_name>fl_axle</joint_name>
      <joint_name>fr_axle</joint_name>
      <joint_name>br_axle</joint_name>
      <joint_name>bl_axle</joint_name>
      <joint_name>r_steer</joint_name>
      <joint_name>l_steer</joint_name>
    </plugin>
  </gazebo>
</robot>
