<?xml version="1.0" ?>
<!-- =================================================================================== -->
<!-- |    This document was autogenerated by xacro from my_ackermann.xacro             | -->
<!-- |    EDITING THIS FILE BY HAND IS NOT RECOMMENDED                                 | -->
<!-- =================================================================================== -->
<robot name="one_wheel">
  <material name="Wheel_Black">
    <color rgba="0.1 0.1 0.1 1"/>
  </material>
  <link name="body_link">
    <visual>
      <geometry>
        <box size="0.5 0.3 0.1"/>
      </geometry>
      <material name="Body_Gray"/>
    </visual>
    <collision>
      <geometry>
        <box size="0.5 0.3 0.1"/>
      </geometry>
    </collision>
    <inertial>
      <mass value="8"/>
      <inertia ixx="0.06666666666666667" ixy="0" ixz="0" iyy="0.17333333333333334" iyz="0" izz="0.17333333333333334"/>
    </inertial>
  </link>
  <gazebo reference="body_link">
    <material value="Gazebo/Wood"/>
  </gazebo>
  <link name="base_link">

    </link>
  <joint name="body_joint" type="fixed">
    <parent link="base_link"/>
    <child link="body_link"/>
    <origin rpy="0 0 0" xyz="0 0 0"/>
  </joint>
  <link name="fr_1">
    <inertial>
      <mass value="0.3"/>
      <inertia ixx="0.0008125000000000002" ixy="0" ixz="0" iyy="0.0008125000000000002" iyz="0" izz="0.0015"/>
    </inertial>
    <visual>
      <origin rpy="0 0 0" xyz="0 0 0"/>
      <geometry>
        <cylinder length="0.05" radius="0.1"/>
      </geometry>
      <material name="Wheel_Black"/>
    </visual>
    <collision>
      <origin rpy="0 0 0" xyz="0 0 0"/>
      <geometry>
        <cylinder length="0.05" radius="0.1"/>
      </geometry>
    </collision>
  </link>
  <link name="r_steer_1">
    <inertial>
      <origin rpy="0 0 0" xyz="0.003381 1.5929e-07 0.02162"/>
      <mass value="1"/>
      <inertia ixx="1.0" ixy="0.0" ixz="0.0" iyy="1.0" iyz="0.0" izz="1.0"/>
    </inertial>
    <visual>
      <origin rpy="0 0 0" xyz="0 0 0"/>
      <geometry>
        <cylinder length="0.05" radius="0.1"/>
      </geometry>
      <material name="Wheel_Black"/>
    </visual>
  </link>
  <joint name="r_steer" type="revolute">
    <origin rpy="0 0 0" xyz="-0.3 0.25 -0.1"/>
    <parent link="body_link"/>
    <child link="r_steer_1"/>
    <axis xyz="0.0 0.0 1.0"/>
    <dynamics damping="0.0" friction="1.0"/>
    <limit effort="100.0" lower="-0.95" upper="0.95" velocity="100"/>
  </joint>
  <joint name="fr_axle" type="continuous">
    <origin rpy="1.570795 0 0" xyz="0.0 0.0 0.0"/>
    <parent link="r_steer_1"/>
    <child link="fr_1"/>
    <axis xyz="0.0 0.0 1.0"/>
    <limit effort="20.0" velocity="20.0"/>
  </joint>
  <gazebo reference="r_steer_1">
    <material value="Gazebo/GreyTransparent "/>
    <mu1>0.2</mu1>
    <mu2>0.2</mu2>
    <selfCollide>true</selfCollide>
  </gazebo>
  <gazebo reference="fr_1">
    <material>Gazebo/DarkGrey</material>
    <mu1>1.0</mu1>
    <mu2>1.0</mu2>
    <slip1>100</slip1>
    <!-- <fdir1>${fdir}</fdir1> -->
    <kp>100000.0</kp>
    <kd>10.0</kd>
    <selfCollide>true</selfCollide>
  </gazebo>
  <link name="fl_1">
    <inertial>
      <mass value="0.3"/>
      <inertia ixx="0.0008125000000000002" ixy="0" ixz="0" iyy="0.0008125000000000002" iyz="0" izz="0.0015"/>
    </inertial>
    <visual>
      <origin rpy="0 0 0" xyz="0 0 0"/>
      <geometry>
        <cylinder length="0.05" radius="0.1"/>
      </geometry>
      <material name="Wheel_Black"/>
    </visual>
    <collision>
      <origin rpy="0 0 0" xyz="0 0 0"/>
      <geometry>
        <cylinder length="0.05" radius="0.1"/>
      </geometry>
    </collision>
  </link>
  <link name="l_steer_1">
    <inertial>
      <origin rpy="0 0 0" xyz="0.003381 1.5929e-07 0.02162"/>
      <mass value="1"/>
      <inertia ixx="1.0" ixy="0.0" ixz="0.0" iyy="1.0" iyz="0.0" izz="1.0"/>
    </inertial>
    <visual>
      <origin rpy="0 0 0" xyz="0 0 0"/>
      <geometry>
        <cylinder length="0.05" radius="0.1"/>
      </geometry>
      <material name="Wheel_Black"/>
    </visual>
  </link>
  <joint name="l_steer" type="revolute">
    <origin rpy="0 0 0" xyz="-0.3 -0.25  -0.1"/>
    <parent link="body_link"/>
    <child link="l_steer_1"/>
    <axis xyz="0.0 0.0 1.0"/>
    <dynamics damping="0.0" friction="1.0"/>
    <limit effort="100.0" lower="-0.95" upper="0.95" velocity="100"/>
  </joint>
  <joint name="fl_axle" type="continuous">
    <origin rpy="1.570795 0 0" xyz="0.0 0.0 0.0"/>
    <parent link="l_steer_1"/>
    <child link="fl_1"/>
    <axis xyz="0.0 0.0 1.0"/>
    <limit effort="20.0" velocity="20.0"/>
  </joint>
  <gazebo reference="l_steer_1">
    <material value="Gazebo/GreyTransparent "/>
    <mu1>0.2</mu1>
    <mu2>0.2</mu2>
    <selfCollide>true</selfCollide>
  </gazebo>
  <gazebo reference="fl_1">
    <material>Gazebo/DarkGrey</material>
    <mu1>1.0</mu1>
    <mu2>1.0</mu2>
    <slip1>100</slip1>
    <!-- <fdir1>${fdir}</fdir1> -->
    <kp>100000.0</kp>
    <kd>10.0</kd>
    <selfCollide>true</selfCollide>
  </gazebo>
  <link name="br_1">
    <inertial>
      <mass value="0.3"/>
      <inertia ixx="0.0008125000000000002" ixy="0" ixz="0" iyy="0.0008125000000000002" iyz="0" izz="0.0015"/>
    </inertial>
    <visual>
      <origin rpy="0 0 0" xyz="0 0 0"/>
      <geometry>
        <cylinder length="0.05" radius="0.1"/>
      </geometry>
      <material name="Wheel_Black"/>
    </visual>
    <collision>
      <origin rpy="0 0 0" xyz="0 0 0"/>
      <geometry>
        <cylinder length="0.05" radius="0.1"/>
      </geometry>
    </collision>
  </link>
  <joint name="br_axle" type="continuous">
    <origin rpy="1.570795 0 0" xyz="0.3 0.25 -0.1"/>
    <parent link="body_link"/>
    <child link="br_1"/>
    <axis xyz="0.0 0.0 1.0"/>
    <limit effort="20.0" velocity="20.0"/>
  </joint>
  <gazebo reference="br_1">
    <material value="Gazebo/Black"/>
    <mu1>1.0</mu1>
    <mu2>1.0</mu2>
    <slip1>100</slip1>
    <!-- <fdir1>${fdir}</fdir1> -->
    <kp>100000.0</kp>
    <kd>10.0</kd>
    <selfCollide>true</selfCollide>
  </gazebo>
  <link name="bl_1">
    <inertial>
      <mass value="0.3"/>
      <inertia ixx="0.0008125000000000002" ixy="0" ixz="0" iyy="0.0008125000000000002" iyz="0" izz="0.0015"/>
    </inertial>
    <visual>
      <origin rpy="0 0 0" xyz="0 0 0"/>
      <geometry>
        <cylinder length="0.05" radius="0.1"/>
      </geometry>
      <material name="Wheel_Black"/>
    </visual>
    <collision>
      <origin rpy="0 0 0" xyz="0 0 0"/>
      <geometry>
        <cylinder length="0.05" radius="0.1"/>
      </geometry>
    </collision>
  </link>
  <joint name="bl_axle" type="continuous">
    <origin rpy="1.570795 0 0" xyz="0.3 -0.25 -0.1"/>
    <parent link="body_link"/>
    <child link="bl_1"/>
    <axis xyz="0.0 0.0 1.0"/>
    <limit effort="20.0" velocity="20.0"/>
  </joint>
  <gazebo reference="bl_1">
    <material value="Gazebo/Black"/>
    <mu1>1.0</mu1>
    <mu2>1.0</mu2>
    <slip1>100</slip1>
    <!-- <fdir1>${fdir}</fdir1> -->
    <kp>100000.0</kp>
    <kd>10.0</kd>
    <selfCollide>true</selfCollide>
  </gazebo>
  <link name="steering_wheel">
    <inertial>
      <mass value="0.8"/>
      <inertia ixx="2.6666666666666663e-05" ixy="0" ixz="0" iyy="2.6666666666666663e-05" iyz="0" izz="4e-05"/>
    </inertial>
    <visual>
      <origin rpy="0 0 0" xyz="0 0 0"/>
      <geometry>
        <cylinder length="0.01" radius="0.01"/>
      </geometry>
      <material name="Wheel_Black"/>
    </visual>
  </link>
  <joint name="steering_joint" type="continuous">
    <origin rpy="0 0 0" xyz="0 0 0.056"/>
    <parent link="body_link"/>
    <child link="steering_wheel"/>
    <axis xyz="0.0 0.0 1.0"/>
    <limit effort="100.0" lower="-6" upper="6" velocity="100"/>
    <dynamics damping="0.0" friction="1.0"/>
  </joint>
  <gazebo>
    <plugin filename="libgazebo_ros_ackermann_drive.so" name="ackermann_drive">
      <ros>
        <namespace>ackermann_dorothy</namespace>
        <remapping>cmd_vel:=cmd_vel</remapping>
        <remapping>odom:=odom</remapping>
        <remapping>distance:=distance</remapping>
      </ros>
      <update_rate>100.0</update_rate>
      <!-- wheels -->
      <front_left_joint>fl_axle</front_left_joint>
      <front_right_joint>fr_axle</front_right_joint>
      <rear_left_joint>bl_axle</rear_left_joint>
      <rear_right_joint>br_axle</rear_right_joint>
      <left_steering_joint>l_steer</left_steering_joint>
      <right_steering_joint>r_steer</right_steering_joint>
      <!-- <steering_wheel_joint>steering_joint</steering_wheel_joint> -->
      <!-- Max absolute steer angle for tyre in radians-->
      <!-- Any cmd_vel angular z greater than this would be capped -->
      <max_steer>0.6</max_steer>
      <!-- Max absolute steering angle of steering wheel -->
      <!-- Max absolute steering angle of steering wheel -->
      <max_steering_angle>2</max_steering_angle>
      <!-- Max absolute linear speed in m/s -->
      <max_speed>10</max_speed>
      <!-- PID tuning -->
      <left_steering_pid_gain>100 0 17 </left_steering_pid_gain>
      <left_steering_i_range>0 0</left_steering_i_range>
      <right_steering_pid_gain>100 0 17</right_steering_pid_gain>
      <right_steering_i_range>0 0</right_steering_i_range>
      <linear_velocity_pid_gain>1 0 0</linear_velocity_pid_gain>
      <linear_velocity_i_range>0 0</linear_velocity_i_range>
      <!-- output -->
      <publish_odom>true</publish_odom>
      <publish_odom_tf>true</publish_odom_tf>
      <publish_wheel_tf>true</publish_wheel_tf>
      <publish_distance>true</publish_distance>
      <odometry_frame>odom</odometry_frame>
      <robot_base_frame>base_link</robot_base_frame>
    </plugin>
  </gazebo>
</robot>
