<?xml version="1.0"?>
<!-- Macros and impelemnatation of wheels, suspensions and steering system -->

<robot xmlns:xacro="http://ros.org/wiki/xacro">
    <material name="Wheel_Black">
        <color rgba="0.1 0.1 0.1 1" />
    </material>
    <xacro:property name="w" value="0.2" />
    <xacro:property name="r" value="0.35" />
    <xacro:property name="m" value="24.5" />
    <xacro:property name="M_PI" value="3.14159265359" />

    <xacro:macro name="cylinder_inertia" params="m r h">
        <inertial>
            <origin xyz="0 0 0" rpy="0 0 0"/>
            <mass value="${m}" />
            <inertia ixx="${m*(3*r*r+h*h)/12}" ixy="0" ixz="0" iyy="${m*(3*r*r+h*h)/12}" iyz="0" izz="${m*r*r/2}" />
        </inertial>
    </xacro:macro>
    <xacro:macro name="wheel_link" params="name">

        <link name="${name}_1">
            <xacro:cylinder_inertia m="${m}" r="${r}" h="${w}"/>
            <visual>
                <origin rpy="0 ${M_PI/2} 0" xyz="0 0 0"/>
                <geometry>
                    <cylinder radius="${r}" length="${w}" />
                </geometry>
                <material name="Wheel_Black"/>
            </visual>
            <collision>
                <origin rpy="0 ${M_PI/2} 0" xyz="0 0 0"/>
                <geometry>
                    <cylinder radius="${r}" length="${w}" />
                </geometry>
            </collision>
        </link>
    </xacro:macro>

    <xacro:macro name="autocar_back_wheel" params="name rpy xyz base_link_name">
        <xacro:wheel_link name="${name}"/>

        <joint name="${name}_axle" type="continuous">
            <origin rpy="0 0 0" xyz="${xyz}"/>
            <parent link="${base_link_name}"/>
            <child link="${name}_1"/>
            <axis xyz="-1.0 0.0 0.0"/>
        </joint>
        <gazebo reference="${name}_1">
            <material value="Gazebo/Black"/>

            <mu1>1.7</mu1>
            <mu2>1.7</mu2>
            <!-- <slip1>100.0</slip1>
            <fdir1>0.0 0.0 1.0</fdir1> -->
            <!-- <kp>5000.0</kp>
            <kd>1.0</kd> -->
            <selfCollide>true</selfCollide>
        </gazebo>
    </xacro:macro>

    <xacro:macro name="autocar_front_wheel" params="name steer_name rpy xyz base_link_name">

        <xacro:wheel_link name="${name}"/>

        <joint name="${name}_axle" type="continuous">
            <origin rpy="0 0 0" xyz="0.05 0.0 0.0"/>
            <parent link="${steer_name}_1"/>
            <child link="${name}_1"/>
            <axis xyz="-1.0 0.0 0.0"/>
        </joint>
        <link name="${steer_name}_1">
            <inertial>
                <origin rpy="0 0 0" xyz="0.003381 1.5929e-07 0.02162"/>
                <mass value="1"/>
                <inertia ixx="1.0" ixy="0.0" ixz="0.0" iyy="1.0" iyz="0.0" izz="1.0"/>
            </inertial>
        </link>

        <joint name="${steer_name}" type="revolute">
            <origin rpy="0 0 0" xyz="${xyz}"/>
            <parent link="${base_link_name}"/>
            <child link="${steer_name}_1"/>
            <axis xyz="0.0 0.0 1.0"/>
            <dynamics damping="0.01" friction="0.01"/>
            <limit effort="1000.0" lower="-0.95" upper="0.95" velocity="100"/>
        </joint>
        <gazebo reference="${steer_name}_1">
            <material>Gazebo/DarkGrey</material>
            <mu1>0.2</mu1>
            <mu2>0.2</mu2>
            <selfCollide>true</selfCollide>
        </gazebo>
        <gazebo reference="${name}_1">
            <material>Gazebo/DarkGrey</material>
            <mu1>1.7</mu1>
            <mu2>1.7</mu2>
            <selfCollide>true</selfCollide>
        </gazebo>
    </xacro:macro>

</robot>