<?xml version="1.0"?>
<!-- Macros and impelemnatation of wheels, suspensions and steering system -->

<robot xmlns:xacro="http://ros.org/wiki/xacro">
    <!-- Ros materials -->
    <material name="Wheel_Black">
        <color rgba="0.1 0.1 0.1 1" />
    </material>
    <material name="Wheel_Silver">
        <color rgba="0.7 0.7 0.7 1" />
    </material>
    <material name="Mechanical">
        <color rgba="1.0 1.0 1.0 1.0" />
    </material>
    <xacro:include filename="lib.xacro" />

    <xacro:property name="wheels_w" value="0.3" />
    <xacro:property name="wheels_lf" value="0.3" />
    <xacro:property name="wheels_lb" value="0.4" />

    <!-- Main wheel & steerins and suspension macro -->
    <!-- ########################################## -->
    <xacro:macro name="make_wheel" params="prefix reflect xyz steerable toe wheel_base_link">
        <xacro:property name="w" value="0.1" />
        <xacro:property name="r" value="0.1" />
        <xacro:property name="m" value="0.1" />
        <xacro:property name="camber" value="${-3.0*M_PI/180}" />
        <xacro:property name="castor" value="0.0" />


        <!-- Wheel link -->
        <link name="${prefix}_wheel_link">
            <visual>
                <geometry>
                    <cylinder radius="${r}" length="${w}" />
                    <!-- <box size="${r} ${r} ${1.1*w}" /> -->
                </geometry>
                <material name="Wheel_Black" />
            </visual>
            <collision>
                <geometry>
                    <cylinder radius="${r}" length="${w}" />
                </geometry>
            </collision>
            <xacro:cylinder_inertia m="${m}" r="${r}" h="${w}" />
        </link>
        <gazebo reference="${prefix}_wheel_link">
            <material value="Gazebo/Black" />
            <mu1>1.0</mu1>
            <mu2>1.0</mu2>
            <slip1>100.0</slip1>
            <fdir1>0.0 0.0 1.0</fdir1>
            <!-- <kp>5000.0</kp>
            <kd>1.0</kd> -->
        </gazebo>

        <!-- Hub link is the non rotating part which the bearing gos on -->
        <!-- The bearing is modeled as continuous joint -->
        <!-- The join is used to control the velocity of the vehicle -->
        <link name="${prefix}_hub_link">
            <visual>
                <geometry>
                    <cylinder radius="${r/2}" length="${w*1.1}" />
                </geometry>
                <material name="Wheel_Silver" />
            </visual>
            <xacro:cylinder_inertia m="0.01" r="0.1" h="0.1" />
        </link>
        <gazebo reference="${prefix}_hub_link">
            <material value="Gazebo/Bricks" />
        </gazebo>
        <joint name="${prefix}_hub_to_wheel" type="continuous">
            <axis xyz="0 0 1" />
            <parent link="${prefix}_hub_link" />
            <child link="${prefix}_wheel_link" />
            <dynamics damping="0.001" friction="0.0001" />
        </joint>
        <!-- This is the lower part of a car strut. 
        It is rigidly connected to the hub and fixes the camber angle -->
        <link name="${prefix}_strut_link">
            <visual>
                <geometry>
                    <cylinder radius="${r/10}" length="${r*2}" />
                </geometry>
                <material name="Mechanical" />
            </visual>
            <xacro:cylinder_inertia m="0.01" r="0.1" h="0.1" />
        </link>
        <gazebo reference="${prefix}_strut_link">
            <material value="Gazebo/GreyTransparent " />
        </gazebo>
        <joint name="${prefix}_strut_to_hub" type="fixed">
            <parent link="${prefix}_strut_dummy_link" />
            <child link="${prefix}_hub_link" />
            <origin rpy="0 ${M_PI/2} 0 " />
        </joint>

        <link name="${prefix}_strut_dummy_link">
            <xacro:cylinder_inertia m="0.01" r="0.1" h="0.1" />
        </link>
        <xacro:if value="${steerable}">
            <joint name="${prefix}_strut_to_strut_dummy" type="revolute">
                <limit lower="${-M_PI/3}" upper="${+M_PI/3}" effort="100" velocity="1" />
                <parent link="${prefix}_strut_link" />
                <child link="${prefix}_strut_dummy_link" />
                <axis xyz="0 0 -1" />
                <origin rpy="0 0 0" />
                <dynamics damping="0.0" friction="0" />
            </joint>
        </xacro:if>
        <xacro:unless value="${steerable}">
            <joint name="${prefix}_strut_to_strut_dummy" type="fixed">
                <parent link="${prefix}_strut_link" />
                <child link="${prefix}_strut_dummy_link" />
            </joint>
        </xacro:unless>

        <gazebo reference="${prefix}_strut_to_strut_dummy">
            <empty></empty>
        </gazebo>
        <!-- Next we create the slider -->
        <link name="${prefix}_strut_base_link">
            <visual>
                <geometry>
                    <cylinder radius="${.7*w}" length="${r/10}" />
                </geometry>
                <material name="Mechanical" />
            </visual>
            <xacro:cylinder_inertia m="0.01" r="0.1" h="0.1" />
        </link>
        <gazebo reference="${prefix}_strut_base_link">
            <material value="Gazebo/GreyTransparent " />
        </gazebo>

        <joint name="${prefix}_strut_base_to_strut" type="prismatic">
            <limit lower="-0.05" upper="+0.05" effort="1" velocity="1" />
            <parent link="${prefix}_strut_base_link" />
            <child link="${prefix}_strut_link" />
            <axis xyz="0 0 1" />
            <origin rpy="${castor} ${reflect*camber} ${-reflect*toe}" />
            <dynamics damping="5" friction="0.0" />
        </joint>
        <gazebo reference="${prefix}_strut_base_to_strut">
            <springStiffness>100</springStiffness>
            <implicitSpringDamper>true</implicitSpringDamper>
            <springReference>-0.07</springReference>
        </gazebo>

        <!-- The pose of one wheel subsystem with relation to the body -->
            <joint name="${prefix}_wheel_base_to_strut" type="fixed">
                <parent link="${wheel_base_link}" />
                <child link="${prefix}_strut_base_link" />
                <origin xyz="${xyz}" rpy="0 0 ${M_PI/2}" />
            </joint>

    </xacro:macro>
</robot>