<sdf version='1.7'>
  <model name='dorothy'>
    <link name='base_footprint'>
      <inertial>
        <pose>-0 -4e-06 0.043589 0 -0 0</pose>
        <mass>0.794</mass>
        <inertia>
          <ixx>0.0135955</ixx>
          <ixy>2.72662e-06</ixy>
          <ixz>-0.00023</ixz>
          <iyy>0.05577</iyy>
          <iyz>2.27465e-07</iyz>
          <izz>0.0551922</izz>
        </inertia>
      </inertial>
      <collision name='base_footprint_fixed_joint_lump__body_link_collision'>
        <pose>0 0 0 0 -0 0</pose>
        <geometry>
          <box>
            <size>1 0.25 0.03</size>
          </box>
        </geometry>
        <surface>
          <contact>
            <ode/>
          </contact>
          <friction>
            <ode/>
          </friction>
        </surface>
      </collision>
      <collision name='base_footprint_fixed_joint_lump__pod_collision_1'>
        <pose>0 0 0.065 0 -0 3.14</pose>
        <geometry>
          <box>
            <size>0.4 0.2 0.1</size>
          </box>
        </geometry>
      </collision>
      <collision name='base_footprint_fixed_joint_lump__camera_front_collision_2'>
        <pose>-0.3 0.000478 0.065 0 -0 3.14</pose>
        <geometry>
          <box>
            <size>0.01 0.04 0.04</size>
          </box>
        </geometry>
        <surface>
          <contact>
            <ode/>
          </contact>
          <friction>
            <ode/>
          </friction>
        </surface>
      </collision>
      <collision name='base_footprint_fixed_joint_lump__camera_left_collision_3'>
        <pose>0.099809 -0.120159 0.115 0 0 -2.51487</pose>
        <geometry>
          <box>
            <size>0.01 0.04 0.04</size>
          </box>
        </geometry>
        <surface>
          <contact>
            <ode/>
          </contact>
          <friction>
            <ode/>
          </friction>
        </surface>
      </collision>
      <collision name='base_footprint_fixed_joint_lump__camera_rear_collision_4'>
        <pose>0.3 -0.000478 0.065 0 0 -0.001595</pose>
        <geometry>
          <box>
            <size>0.01 0.04 0.04</size>
          </box>
        </geometry>
        <surface>
          <contact>
            <ode/>
          </contact>
          <friction>
            <ode/>
          </friction>
        </surface>
      </collision>
      <collision name='base_footprint_fixed_joint_lump__camera_right_collision_5'>
        <pose>0.100191 0.119841 0.115 0 -0 2.51168</pose>
        <geometry>
          <box>
            <size>0.01 0.04 0.04</size>
          </box>
        </geometry>
        <surface>
          <contact>
            <ode/>
          </contact>
          <friction>
            <ode/>
          </friction>
        </surface>
      </collision>
      <collision name='base_footprint_fixed_joint_lump__laser_collision_6'>
        <pose>0.015 -4.8e-05 0.2085 0 0 -0.003185</pose>
        <geometry>
          <cylinder>
            <length>0.0315</length>
            <radius>0.055</radius>
          </cylinder>
        </geometry>
        <surface>
          <contact>
            <ode/>
          </contact>
          <friction>
            <ode/>
          </friction>
        </surface>
      </collision>
      <visual name='base_footprint_fixed_joint_lump__body_link_visual'>
        <pose>0 0 0 0 -0 0</pose>
        <geometry>
          <box>
            <size>1 0.25 0.03</size>
          </box>
        </geometry>
        <material>
          <script>
            <name>Gazebo/Wood</name>
            <uri>file://media/materials/scripts/gazebo.material</uri>
          </script>
        </material>
      </visual>
      <visual name='base_footprint_fixed_joint_lump__left_back_strut_base_link_visual_1'>
        <pose>-0.4 0.3 0 0 -0 1.57079</pose>
        <geometry>
          <cylinder>
            <length>0.01</length>
            <radius>0.07</radius>
          </cylinder>
        </geometry>
        <material>
          <script>
            <name>Gazebo/GreyTransparent</name>
            <uri>file://media/materials/scripts/gazebo.material</uri>
          </script>
        </material>
      </visual>
      <visual name='base_footprint_fixed_joint_lump__left_front_strut_base_link_visual_2'>
        <pose>0.3 0.3 0 0 -0 1.57079</pose>
        <geometry>
          <cylinder>
            <length>0.01</length>
            <radius>0.07</radius>
          </cylinder>
        </geometry>
        <material>
          <script>
            <name>Gazebo/GreyTransparent</name>
            <uri>file://media/materials/scripts/gazebo.material</uri>
          </script>
        </material>
      </visual>
      <visual name='base_footprint_fixed_joint_lump__pod_visual_3'>
        <pose>0 0 0.065 0 -0 3.14</pose>
        <geometry>
          <box>
            <size>0.4 0.2 0.1</size>
          </box>
        </geometry>
      </visual>
      <visual name='base_footprint_fixed_joint_lump__camera_front_visual_4'>
        <pose>-0.3 0.000478 0.065 0 -0 3.14</pose>
        <geometry>
          <box>
            <size>0.01 0.04 0.04</size>
          </box>
        </geometry>
        <material>
          <script>
            <name>Gazebo/Red</name>
            <uri>file://media/materials/scripts/gazebo.material</uri>
          </script>
        </material>
      </visual>
      <visual name='base_footprint_fixed_joint_lump__camera_left_visual_5'>
        <pose>0.099809 -0.120159 0.115 0 0 -2.51487</pose>
        <geometry>
          <box>
            <size>0.01 0.04 0.04</size>
          </box>
        </geometry>
        <material>
          <script>
            <name>Gazebo/Red</name>
            <uri>file://media/materials/scripts/gazebo.material</uri>
          </script>
        </material>
      </visual>
      <visual name='base_footprint_fixed_joint_lump__camera_rear_visual_6'>
        <pose>0.3 -0.000478 0.065 0 0 -0.001595</pose>
        <geometry>
          <box>
            <size>0.01 0.04 0.04</size>
          </box>
        </geometry>
        <material>
          <script>
            <name>Gazebo/Red</name>
            <uri>file://media/materials/scripts/gazebo.material</uri>
          </script>
        </material>
      </visual>
      <visual name='base_footprint_fixed_joint_lump__camera_right_visual_7'>
        <pose>0.100191 0.119841 0.115 0 -0 2.51168</pose>
        <geometry>
          <box>
            <size>0.01 0.04 0.04</size>
          </box>
        </geometry>
        <material>
          <script>
            <name>Gazebo/Red</name>
            <uri>file://media/materials/scripts/gazebo.material</uri>
          </script>
        </material>
      </visual>
      <visual name='base_footprint_fixed_joint_lump__laser_visual_8'>
        <pose>0 0 0.215 0 0 -0.003185</pose>
        <geometry>
          <cylinder>
            <length>0.0315</length>
            <radius>0.055</radius>
          </cylinder>
        </geometry>
        <material>
          <script>
            <name>Gazebo/FlatBlack</name>
            <uri>file://media/materials/scripts/gazebo.material</uri>
          </script>
        </material>
      </visual>
      <visual name='base_footprint_fixed_joint_lump__right_back_strut_base_link_visual_9'>
        <pose>-0.4 -0.3 0 0 -0 1.57079</pose>
        <geometry>
          <cylinder>
            <length>0.01</length>
            <radius>0.07</radius>
          </cylinder>
        </geometry>
        <material>
          <script>
            <name>Gazebo/GreyTransparent</name>
            <uri>file://media/materials/scripts/gazebo.material</uri>
          </script>
        </material>
      </visual>
      <visual name='base_footprint_fixed_joint_lump__right_front_strut_base_link_visual_10'>
        <pose>0.3 -0.3 0 0 -0 1.57079</pose>
        <geometry>
          <cylinder>
            <length>0.01</length>
            <radius>0.07</radius>
          </cylinder>
        </geometry>
        <material>
          <script>
            <name>Gazebo/GreyTransparent</name>
            <uri>file://media/materials/scripts/gazebo.material</uri>
          </script>
        </material>
      </visual>
      <sensor name='imu_sensor' type='imu'>
        <always_on>1</always_on>
        <update_rate>1000</update_rate>
        <pose>0 0 0 0 -0 0</pose>
        <gravity>1</gravity>
      </sensor>
      <sensor name='camera_front_sensor' type='camera'>
        <camera>
          <horizontal_fov>1.5</horizontal_fov>
          <image>
            <width>640</width>
            <height>480</height>
          </image>
          <clip>
            <near>0.1</near>
            <far>1000</far>
          </clip>
        </camera>
        <always_on>1</always_on>
        <update_rate>10</update_rate>
        <visualize>0</visualize>
        <camera name='camera_front'>
          <distortion>
            <k1>0</k1>
            <k2>0</k2>
            <k3>0</k3>
            <p1>0</p1>
            <p2>0</p2>
            <center>0.5 0.5</center>
          </distortion>
          <horizontal_fov>1.047</horizontal_fov>
          <image>
            <width>320</width>
            <height>240</height>
          </image>
          <clip>
            <near>0.1</near>
            <far>100</far>
          </clip>
        </camera>
        <plugin name='camera_controller' filename='libgazebo_ros_camera.so'>
          <ros>
            <namespace/>
          </ros>
          <hack_baseline>0.07</hack_baseline>
          <frame_name>camera_front</frame_name>
        </plugin>
        <pose>-0.3 0.000478 0.065 0 -0 3.14</pose>
      </sensor>
      <sensor name='camera_left_sensor' type='camera'>
        <camera>
          <horizontal_fov>1.5</horizontal_fov>
          <image>
            <width>640</width>
            <height>480</height>
          </image>
          <clip>
            <near>0.1</near>
            <far>1000</far>
          </clip>
        </camera>
        <always_on>1</always_on>
        <update_rate>10</update_rate>
        <visualize>0</visualize>
        <camera name='camera_left'>
          <distortion>
            <k1>0</k1>
            <k2>0</k2>
            <k3>0</k3>
            <p1>0</p1>
            <p2>0</p2>
            <center>0.5 0.5</center>
          </distortion>
          <horizontal_fov>1.047</horizontal_fov>
          <image>
            <width>320</width>
            <height>240</height>
          </image>
          <clip>
            <near>0.1</near>
            <far>100</far>
          </clip>
        </camera>
        <plugin name='camera_controller' filename='libgazebo_ros_camera.so'>
          <ros>
            <namespace/>
          </ros>
          <hack_baseline>0.07</hack_baseline>
          <frame_name>camera_left</frame_name>
        </plugin>
        <pose>0.099809 -0.120159 0.115 0 -0 -2.51487</pose>
      </sensor>
      <sensor name='camera_rear_sensor' type='camera'>
        <camera>
          <horizontal_fov>1.5</horizontal_fov>
          <image>
            <width>640</width>
            <height>480</height>
          </image>
          <clip>
            <near>0.1</near>
            <far>1000</far>
          </clip>
        </camera>
        <always_on>1</always_on>
        <update_rate>10</update_rate>
        <visualize>0</visualize>
        <camera name='camera_rear'>
          <distortion>
            <k1>0</k1>
            <k2>0</k2>
            <k3>0</k3>
            <p1>0</p1>
            <p2>0</p2>
            <center>0.5 0.5</center>
          </distortion>
          <horizontal_fov>1.047</horizontal_fov>
          <image>
            <width>320</width>
            <height>240</height>
          </image>
          <clip>
            <near>0.1</near>
            <far>100</far>
          </clip>
        </camera>
        <plugin name='camera_controller' filename='libgazebo_ros_camera.so'>
          <ros>
            <namespace/>
          </ros>
          <hack_baseline>0.07</hack_baseline>
          <frame_name>camera_rear</frame_name>
        </plugin>
        <pose>0.3 -0.000478 0.065 0 -0 -0.001595</pose>
      </sensor>
      <sensor name='camera_right_sensor' type='camera'>
        <camera>
          <horizontal_fov>1.5</horizontal_fov>
          <image>
            <width>640</width>
            <height>480</height>
          </image>
          <clip>
            <near>0.1</near>
            <far>1000</far>
          </clip>
        </camera>
        <always_on>1</always_on>
        <update_rate>10</update_rate>
        <visualize>0</visualize>
        <camera name='camera_right'>
          <distortion>
            <k1>0</k1>
            <k2>0</k2>
            <k3>0</k3>
            <p1>0</p1>
            <p2>0</p2>
            <center>0.5 0.5</center>
          </distortion>
          <horizontal_fov>1.047</horizontal_fov>
          <image>
            <width>320</width>
            <height>240</height>
          </image>
          <clip>
            <near>0.1</near>
            <far>100</far>
          </clip>
        </camera>
        <plugin name='camera_controller' filename='libgazebo_ros_camera.so'>
          <ros>
            <namespace/>
          </ros>
          <hack_baseline>0.07</hack_baseline>
          <frame_name>camera_right</frame_name>
        </plugin>
        <pose>0.100191 0.119841 0.115 0 -0 2.51168</pose>
      </sensor>
      <sensor name='lidar_sensor' type='ray'>
        <visualize>0</visualize>
        <update_rate>15</update_rate>
        <ray>
          <scan>
            <horizontal>
              <samples>360</samples>
              <resolution>1</resolution>
              <min_angle>0</min_angle>
              <max_angle>6.28319</max_angle>
            </horizontal>
          </scan>
          <range>
            <min>0.12</min>
            <max>10</max>
            <resolution>0.05</resolution>
          </range>
          <noise>
            <type>gaussian</type>
            <mean>0</mean>
            <stddev>0.01</stddev>
          </noise>
        </ray>
        <plugin name='scan' filename='libgazebo_ros_ray_sensor.so'>
          <ros>
            <remapping>~/out:=scan</remapping>
          </ros>
          <output_type>sensor_msgs/LaserScan</output_type>
          <frame_name>laser</frame_name>
        </plugin>
        <pose>0 0 0.215 0 -0 -0.003185</pose>
      </sensor>
    </link>
    <joint name='left_back_strut_base_to_strut' type='prismatic'>
      <pose relative_to='base_footprint'>-0.4 0.3 0 0 -0.05236 1.52716</pose>
      <parent>base_footprint</parent>
      <child>left_back_strut_link</child>
      <axis>
        <xyz>0 0 1</xyz>
        <limit>
          <lower>-0.05</lower>
          <upper>0.05</upper>
          <effort>1</effort>
          <velocity>1</velocity>
        </limit>
        <dynamics>
          <damping>5</damping>
          <friction>0</friction>
          <spring_reference>-0.07</spring_reference>
          <spring_stiffness>100</spring_stiffness>
        </dynamics>
      </axis>
      <physics>
        <ode>
          <implicit_spring_damper>1</implicit_spring_damper>
          <cfm_damping>1</cfm_damping>
          <limit>
            <cfm>0</cfm>
            <erp>0.2</erp>
          </limit>
        </ode>
      </physics>
    </joint>
    <link name='left_back_strut_link'>
      <pose relative_to='left_back_strut_base_to_strut'>0 0 0 0 -0 0</pose>
      <inertial>
        <pose>0 0 0 0 -0 0</pose>
        <mass>0.03</mass>
        <inertia>
          <ixx>0.000116667</ixx>
          <ixy>0</ixy>
          <ixz>1.02054e-21</ixz>
          <iyy>0.0001</iyy>
          <iyz>0</iyz>
          <izz>0.000133333</izz>
        </inertia>
      </inertial>
      <visual name='left_back_strut_link_visual'>
        <pose>0 0 0 0 -0 0</pose>
        <geometry>
          <cylinder>
            <length>0.2</length>
            <radius>0.01</radius>
          </cylinder>
        </geometry>
        <material>
          <script>
            <name>Gazebo/GreyTransparent</name>
            <uri>file://media/materials/scripts/gazebo.material</uri>
          </script>
        </material>
      </visual>
      <visual name='left_back_strut_link_fixed_joint_lump__left_back_hub_link_visual_1'>
        <pose>0 0 0 0 1.5708 0</pose>
        <geometry>
          <cylinder>
            <length>0.11</length>
            <radius>0.05</radius>
          </cylinder>
        </geometry>
        <material>
          <script>
            <name>Gazebo/Bricks</name>
            <uri>file://media/materials/scripts/gazebo.material</uri>
          </script>
        </material>
      </visual>
    </link>
    <joint name='left_back_hub_to_wheel' type='revolute'>
      <pose relative_to='left_back_strut_link'>0 0 0 0 1.57079 0</pose>
      <parent>left_back_strut_link</parent>
      <child>left_back_wheel_link</child>
      <axis>
        <xyz>0 0 1</xyz>
        <limit>
          <lower>-1e+16</lower>
          <upper>1e+16</upper>
        </limit>
        <dynamics>
          <damping>0.001</damping>
          <friction>0.0001</friction>
          <spring_reference>0</spring_reference>
          <spring_stiffness>0</spring_stiffness>
        </dynamics>
      </axis>
    </joint>
    <link name='left_back_wheel_link'>
      <pose relative_to='left_back_hub_to_wheel'>0 0 0 0 -0 0</pose>
      <inertial>
        <pose>0 0 0 0 -0 0</pose>
        <mass>0.1</mass>
        <inertia>
          <ixx>0.000333333</ixx>
          <ixy>0</ixy>
          <ixz>0</ixz>
          <iyy>0.000333333</iyy>
          <iyz>0</iyz>
          <izz>0.0005</izz>
        </inertia>
      </inertial>
      <collision name='left_back_wheel_link_collision'>
        <pose>0 0 0 0 -0 0</pose>
        <geometry>
          <cylinder>
            <length>0.1</length>
            <radius>0.1</radius>
          </cylinder>
        </geometry>
        <surface>
          <contact>
            <ode/>
          </contact>
          <friction>
            <ode>
              <mu>1</mu>
              <mu2>1</mu2>
              <fdir1>0 0 1</fdir1>
            </ode>
          </friction>
        </surface>
      </collision>
      <visual name='left_back_wheel_link_visual'>
        <pose>0 0 0 0 -0 0</pose>
        <geometry>
          <cylinder>
            <length>0.1</length>
            <radius>0.1</radius>
          </cylinder>
        </geometry>
        <material>
          <script>
            <name>Gazebo/Black</name>
            <uri>file://media/materials/scripts/gazebo.material</uri>
          </script>
        </material>
      </visual>
      <slip1>100.0</slip1>
    </link>
    <joint name='left_front_strut_base_to_strut' type='prismatic'>
      <pose relative_to='base_footprint'>0.3 0.3 0 0 -0.05236 1.57079</pose>
      <parent>base_footprint</parent>
      <child>left_front_strut_link</child>
      <axis>
        <xyz>0 0 1</xyz>
        <limit>
          <lower>-0.05</lower>
          <upper>0.05</upper>
          <effort>1</effort>
          <velocity>1</velocity>
        </limit>
        <dynamics>
          <damping>5</damping>
          <friction>0</friction>
          <spring_reference>-0.07</spring_reference>
          <spring_stiffness>100</spring_stiffness>
        </dynamics>
      </axis>
      <physics>
        <ode>
          <implicit_spring_damper>1</implicit_spring_damper>
          <cfm_damping>1</cfm_damping>
          <limit>
            <cfm>0</cfm>
            <erp>0.2</erp>
          </limit>
        </ode>
      </physics>
    </joint>
    <link name='left_front_strut_link'>
      <pose relative_to='left_front_strut_base_to_strut'>0 0 0 0 -0 0</pose>
      <inertial>
        <pose>0 0 0 0 -0 0</pose>
        <mass>0.01</mass>
        <inertia>
          <ixx>3.33333e-05</ixx>
          <ixy>0</ixy>
          <ixz>0</ixz>
          <iyy>3.33333e-05</iyy>
          <iyz>0</iyz>
          <izz>5e-05</izz>
        </inertia>
      </inertial>
      <visual name='left_front_strut_link_visual'>
        <pose>0 0 0 0 -0 0</pose>
        <geometry>
          <cylinder>
            <length>0.2</length>
            <radius>0.01</radius>
          </cylinder>
        </geometry>
        <material>
          <script>
            <name>Gazebo/GreyTransparent</name>
            <uri>file://media/materials/scripts/gazebo.material</uri>
          </script>
        </material>
      </visual>
    </link>
    <joint name='left_front_strut_to_strut_dummy' type='revolute'>
      <pose relative_to='left_front_strut_link'>0 0 0 0 -0 0</pose>
      <parent>left_front_strut_link</parent>
      <child>left_front_strut_dummy_link</child>
      <axis>
        <xyz>0 0 -1</xyz>
        <limit>
          <lower>-1.0472</lower>
          <upper>1.0472</upper>
          <effort>100</effort>
          <velocity>1</velocity>
        </limit>
        <dynamics>
          <damping>0</damping>
          <friction>0</friction>
          <spring_reference>0</spring_reference>
          <spring_stiffness>0</spring_stiffness>
        </dynamics>
      </axis>
      <physics>
        <ode>
          <limit>
            <cfm>0</cfm>
            <erp>0.2</erp>
          </limit>
        </ode>
      </physics>
      <empty/>
    </joint>
    <link name='left_front_strut_dummy_link'>
      <pose relative_to='left_front_strut_to_strut_dummy'>0 0 0 0 -0 0</pose>
      <inertial>
        <pose>0 0 0 0 -0 0</pose>
        <mass>0.02</mass>
        <inertia>
          <ixx>8.33333e-05</ixx>
          <ixy>0</ixy>
          <ixz>1.02054e-21</ixz>
          <iyy>6.66667e-05</iyy>
          <iyz>0</iyz>
          <izz>8.33333e-05</izz>
        </inertia>
      </inertial>
      <visual name='left_front_strut_dummy_link_fixed_joint_lump__left_front_hub_link_visual'>
        <pose>0 0 0 0 1.5708 0</pose>
        <geometry>
          <cylinder>
            <length>0.11</length>
            <radius>0.05</radius>
          </cylinder>
        </geometry>
        <material>
          <script>
            <name>Gazebo/Bricks</name>
            <uri>file://media/materials/scripts/gazebo.material</uri>
          </script>
        </material>
      </visual>
    </link>
    <joint name='left_front_hub_to_wheel' type='revolute'>
      <pose relative_to='left_front_strut_dummy_link'>0 0 0 0 1.57079 0</pose>
      <parent>left_front_strut_dummy_link</parent>
      <child>left_front_wheel_link</child>
      <axis>
        <xyz>0 0 1</xyz>
        <limit>
          <lower>-1e+16</lower>
          <upper>1e+16</upper>
        </limit>
        <dynamics>
          <damping>0.001</damping>
          <friction>0.0001</friction>
          <spring_reference>0</spring_reference>
          <spring_stiffness>0</spring_stiffness>
        </dynamics>
      </axis>
    </joint>
    <link name='left_front_wheel_link'>
      <pose relative_to='left_front_hub_to_wheel'>0 0 0 0 -0 0</pose>
      <inertial>
        <pose>0 0 0 0 -0 0</pose>
        <mass>0.1</mass>
        <inertia>
          <ixx>0.000333333</ixx>
          <ixy>0</ixy>
          <ixz>0</ixz>
          <iyy>0.000333333</iyy>
          <iyz>0</iyz>
          <izz>0.0005</izz>
        </inertia>
      </inertial>
      <collision name='left_front_wheel_link_collision'>
        <pose>0 0 0 0 -0 0</pose>
        <geometry>
          <cylinder>
            <length>0.1</length>
            <radius>0.1</radius>
          </cylinder>
        </geometry>
        <surface>
          <contact>
            <ode/>
          </contact>
          <friction>
            <ode>
              <mu>1</mu>
              <mu2>1</mu2>
              <fdir1>0 0 1</fdir1>
            </ode>
          </friction>
        </surface>
      </collision>
      <visual name='left_front_wheel_link_visual'>
        <pose>0 0 0 0 -0 0</pose>
        <geometry>
          <cylinder>
            <length>0.1</length>
            <radius>0.1</radius>
          </cylinder>
        </geometry>
        <material>
          <script>
            <name>Gazebo/Black</name>
            <uri>file://media/materials/scripts/gazebo.material</uri>
          </script>
        </material>
      </visual>
      <slip1>100.0</slip1>
    </link>
    <joint name='right_back_strut_base_to_strut' type='prismatic'>
      <pose relative_to='base_footprint'>-0.4 -0.3 0 -0 0.05236 1.61443</pose>
      <parent>base_footprint</parent>
      <child>right_back_strut_link</child>
      <axis>
        <xyz>0 0 1</xyz>
        <limit>
          <lower>-0.05</lower>
          <upper>0.05</upper>
          <effort>1</effort>
          <velocity>1</velocity>
        </limit>
        <dynamics>
          <damping>5</damping>
          <friction>0</friction>
          <spring_reference>-0.07</spring_reference>
          <spring_stiffness>100</spring_stiffness>
        </dynamics>
      </axis>
      <physics>
        <ode>
          <implicit_spring_damper>1</implicit_spring_damper>
          <cfm_damping>1</cfm_damping>
          <limit>
            <cfm>0</cfm>
            <erp>0.2</erp>
          </limit>
        </ode>
      </physics>
    </joint>
    <link name='right_back_strut_link'>
      <pose relative_to='right_back_strut_base_to_strut'>0 0 0 0 -0 0</pose>
      <inertial>
        <pose>0 0 0 0 -0 0</pose>
        <mass>0.03</mass>
        <inertia>
          <ixx>0.000116667</ixx>
          <ixy>0</ixy>
          <ixz>1.02054e-21</ixz>
          <iyy>0.0001</iyy>
          <iyz>0</iyz>
          <izz>0.000133333</izz>
        </inertia>
      </inertial>
      <visual name='right_back_strut_link_visual'>
        <pose>0 0 0 0 -0 0</pose>
        <geometry>
          <cylinder>
            <length>0.2</length>
            <radius>0.01</radius>
          </cylinder>
        </geometry>
        <material>
          <script>
            <name>Gazebo/GreyTransparent</name>
            <uri>file://media/materials/scripts/gazebo.material</uri>
          </script>
        </material>
      </visual>
      <visual name='right_back_strut_link_fixed_joint_lump__right_back_hub_link_visual_1'>
        <pose>0 0 0 0 1.5708 0</pose>
        <geometry>
          <cylinder>
            <length>0.11</length>
            <radius>0.05</radius>
          </cylinder>
        </geometry>
        <material>
          <script>
            <name>Gazebo/Bricks</name>
            <uri>file://media/materials/scripts/gazebo.material</uri>
          </script>
        </material>
      </visual>
    </link>
    <joint name='right_back_hub_to_wheel' type='revolute'>
      <pose relative_to='right_back_strut_link'>0 0 0 0 1.57079 0</pose>
      <parent>right_back_strut_link</parent>
      <child>right_back_wheel_link</child>
      <axis>
        <xyz>0 0 1</xyz>
        <limit>
          <lower>-1e+16</lower>
          <upper>1e+16</upper>
        </limit>
        <dynamics>
          <damping>0.001</damping>
          <friction>0.0001</friction>
          <spring_reference>0</spring_reference>
          <spring_stiffness>0</spring_stiffness>
        </dynamics>
      </axis>
    </joint>
    <link name='right_back_wheel_link'>
      <pose relative_to='right_back_hub_to_wheel'>0 0 0 0 -0 0</pose>
      <inertial>
        <pose>0 0 0 0 -0 0</pose>
        <mass>0.1</mass>
        <inertia>
          <ixx>0.000333333</ixx>
          <ixy>0</ixy>
          <ixz>0</ixz>
          <iyy>0.000333333</iyy>
          <iyz>0</iyz>
          <izz>0.0005</izz>
        </inertia>
      </inertial>
      <collision name='right_back_wheel_link_collision'>
        <pose>0 0 0 0 -0 0</pose>
        <geometry>
          <cylinder>
            <length>0.1</length>
            <radius>0.1</radius>
          </cylinder>
        </geometry>
        <surface>
          <contact>
            <ode/>
          </contact>
          <friction>
            <ode>
              <mu>1</mu>
              <mu2>1</mu2>
              <fdir1>0 0 1</fdir1>
            </ode>
          </friction>
        </surface>
      </collision>
      <visual name='right_back_wheel_link_visual'>
        <pose>0 0 0 0 -0 0</pose>
        <geometry>
          <cylinder>
            <length>0.1</length>
            <radius>0.1</radius>
          </cylinder>
        </geometry>
        <material>
          <script>
            <name>Gazebo/Black</name>
            <uri>file://media/materials/scripts/gazebo.material</uri>
          </script>
        </material>
      </visual>
      <slip1>100.0</slip1>
    </link>
    <joint name='right_front_strut_base_to_strut' type='prismatic'>
      <pose relative_to='base_footprint'>0.3 -0.3 0 -0 0.05236 1.57079</pose>
      <parent>base_footprint</parent>
      <child>right_front_strut_link</child>
      <axis>
        <xyz>0 0 1</xyz>
        <limit>
          <lower>-0.05</lower>
          <upper>0.05</upper>
          <effort>1</effort>
          <velocity>1</velocity>
        </limit>
        <dynamics>
          <damping>5</damping>
          <friction>0</friction>
          <spring_reference>-0.07</spring_reference>
          <spring_stiffness>100</spring_stiffness>
        </dynamics>
      </axis>
      <physics>
        <ode>
          <implicit_spring_damper>1</implicit_spring_damper>
          <cfm_damping>1</cfm_damping>
          <limit>
            <cfm>0</cfm>
            <erp>0.2</erp>
          </limit>
        </ode>
      </physics>
    </joint>
    <link name='right_front_strut_link'>
      <pose relative_to='right_front_strut_base_to_strut'>0 0 0 0 -0 0</pose>
      <inertial>
        <pose>0 0 0 0 -0 0</pose>
        <mass>0.01</mass>
        <inertia>
          <ixx>3.33333e-05</ixx>
          <ixy>0</ixy>
          <ixz>0</ixz>
          <iyy>3.33333e-05</iyy>
          <iyz>0</iyz>
          <izz>5e-05</izz>
        </inertia>
      </inertial>
      <visual name='right_front_strut_link_visual'>
        <pose>0 0 0 0 -0 0</pose>
        <geometry>
          <cylinder>
            <length>0.2</length>
            <radius>0.01</radius>
          </cylinder>
        </geometry>
        <material>
          <script>
            <name>Gazebo/GreyTransparent</name>
            <uri>file://media/materials/scripts/gazebo.material</uri>
          </script>
        </material>
      </visual>
    </link>
    <joint name='right_front_strut_to_strut_dummy' type='revolute'>
      <pose relative_to='right_front_strut_link'>0 0 0 0 -0 0</pose>
      <parent>right_front_strut_link</parent>
      <child>right_front_strut_dummy_link</child>
      <axis>
        <xyz>0 0 -1</xyz>
        <limit>
          <lower>-1.0472</lower>
          <upper>1.0472</upper>
          <effort>100</effort>
          <velocity>1</velocity>
        </limit>
        <dynamics>
          <damping>0</damping>
          <friction>0</friction>
          <spring_reference>0</spring_reference>
          <spring_stiffness>0</spring_stiffness>
        </dynamics>
      </axis>
      <physics>
        <ode>
          <limit>
            <cfm>0</cfm>
            <erp>0.2</erp>
          </limit>
        </ode>
      </physics>
      <empty/>
    </joint>
    <link name='right_front_strut_dummy_link'>
      <pose relative_to='right_front_strut_to_strut_dummy'>0 0 0 0 -0 0</pose>
      <inertial>
        <pose>0 0 0 0 -0 0</pose>
        <mass>0.02</mass>
        <inertia>
          <ixx>8.33333e-05</ixx>
          <ixy>0</ixy>
          <ixz>1.02054e-21</ixz>
          <iyy>6.66667e-05</iyy>
          <iyz>0</iyz>
          <izz>8.33333e-05</izz>
        </inertia>
      </inertial>
      <visual name='right_front_strut_dummy_link_fixed_joint_lump__right_front_hub_link_visual'>
        <pose>0 0 0 0 1.5708 0</pose>
        <geometry>
          <cylinder>
            <length>0.11</length>
            <radius>0.05</radius>
          </cylinder>
        </geometry>
        <material>
          <script>
            <name>Gazebo/Bricks</name>
            <uri>file://media/materials/scripts/gazebo.material</uri>
          </script>
        </material>
      </visual>
    </link>
    <joint name='right_front_hub_to_wheel' type='revolute'>
      <pose relative_to='right_front_strut_dummy_link'>0 0 0 0 1.57079 0</pose>
      <parent>right_front_strut_dummy_link</parent>
      <child>right_front_wheel_link</child>
      <axis>
        <xyz>0 0 1</xyz>
        <limit>
          <lower>-1e+16</lower>
          <upper>1e+16</upper>
        </limit>
        <dynamics>
          <damping>0.001</damping>
          <friction>0.0001</friction>
          <spring_reference>0</spring_reference>
          <spring_stiffness>0</spring_stiffness>
        </dynamics>
      </axis>
    </joint>
    <link name='right_front_wheel_link'>
      <pose relative_to='right_front_hub_to_wheel'>0 0 0 0 -0 0</pose>
      <inertial>
        <pose>0 0 0 0 -0 0</pose>
        <mass>0.1</mass>
        <inertia>
          <ixx>0.000333333</ixx>
          <ixy>0</ixy>
          <ixz>0</ixz>
          <iyy>0.000333333</iyy>
          <iyz>0</iyz>
          <izz>0.0005</izz>
        </inertia>
      </inertial>
      <collision name='right_front_wheel_link_collision'>
        <pose>0 0 0 0 -0 0</pose>
        <geometry>
          <cylinder>
            <length>0.1</length>
            <radius>0.1</radius>
          </cylinder>
        </geometry>
        <surface>
          <contact>
            <ode/>
          </contact>
          <friction>
            <ode>
              <mu>1</mu>
              <mu2>1</mu2>
              <fdir1>0 0 1</fdir1>
            </ode>
          </friction>
        </surface>
      </collision>
      <visual name='right_front_wheel_link_visual'>
        <pose>0 0 0 0 -0 0</pose>
        <geometry>
          <cylinder>
            <length>0.1</length>
            <radius>0.1</radius>
          </cylinder>
        </geometry>
        <material>
          <script>
            <name>Gazebo/Black</name>
            <uri>file://media/materials/scripts/gazebo.material</uri>
          </script>
        </material>
      </visual>
      <slip1>100.0</slip1>
    </link>
    <static>0</static>
    <plugin name='ArduCopter_Plugin' filename='libArduPilotPlugin.so'>
      <fdm_addr>127.0.0.1</fdm_addr>
      <fdm_port_in>9002</fdm_port_in>
      <fdm_port_out>9003</fdm_port_out>
      <modelXYZToAirplaneXForwardZDown>0 0 0 3.14159 0 0</modelXYZToAirplaneXForwardZDown>
      <gazeboXYZToNED>0 0 0 3.14159 0 0</gazeboXYZToNED>
      <imuName>imu_sensor</imuName>
      <connectionTimeoutMaxCount>5</connectionTimeoutMaxCount>
      <control channel='2'>
        <type>VELOCITY</type>
        <offset>-0.5</offset>
        <p_gain>10</p_gain>
        <jointName>left_back_hub_to_wheel</jointName>
        <multiplier>150</multiplier>
      </control>
      <control channel='2'>
        <type>VELOCITY</type>
        <offset>-0.5</offset>
        <p_gain>10</p_gain>
        <jointName>left_front_hub_to_wheel</jointName>
        <multiplier>150</multiplier>
      </control>
      <control channel='2'>
        <type>VELOCITY</type>
        <offset>-0.5</offset>
        <p_gain>10</p_gain>
        <jointName>right_back_hub_to_wheel</jointName>
        <multiplier>150</multiplier>
      </control>
      <control channel='2'>
        <type>VELOCITY</type>
        <offset>-0.5</offset>
        <p_gain>10</p_gain>
        <jointName>right_front_hub_to_wheel</jointName>
        <multiplier>150</multiplier>
      </control>
      <control channel='0'>
        <type>POSITION</type>
        <offset>-0.5</offset>
        <p_gain>30</p_gain>
        <cmd_max>100</cmd_max>
        <cmd_min>-100</cmd_min>
        <jointName>left_front_strut_to_strut_dummy</jointName>
        <multiplier>1.570795</multiplier>
      </control>
      <control channel='0'>
        <type>POSITION</type>
        <offset>-0.5</offset>
        <p_gain>30</p_gain>
        <cmd_max>100</cmd_max>
        <cmd_min>-100</cmd_min>
        <jointName>right_front_strut_to_strut_dummy</jointName>
        <multiplier>1.570795</multiplier>
      </control>
    </plugin>
  </model>
</sdf>
