<sdf version='1.7'>
  <model name='ngeeann_av'>
    <link name='base_link'>
      <inertial>
        <pose>1e-06 0.07307 0.6752 0 -0 0</pose>
        <mass>1580</mass>
        <inertia>
          <ixx>1997.86</ixx>
          <ixy>-3e-05</ixy>
          <ixz>-9.99999e-07</ixz>
          <iyy>442.769</iyy>
          <iyz>62.5206</iyz>
          <izz>2238.05</izz>
        </inertia>
      </inertial>
      <collision name='base_link_fixed_joint_lump__chassis_link_collision'>
        <pose>0 0 0.4936 0 -0 0</pose>
        <geometry>
          <mesh>
            <scale>0.001 0.001 0.001</scale>
            <uri>model://ngeeann_av/meshes/chassis_link.stl</uri>
          </mesh>
        </geometry>
      </collision>
      <collision name='base_link_fixed_joint_lump__hokuyo_link_collision_1'>
        <pose>0 2.34 0.7336 0 -0 2.5708</pose>
        <geometry>
          <box>
            <size>0.05 0.05 0.05</size>
          </box>
        </geometry>
      </collision>
      <collision name='base_link_fixed_joint_lump__spoiler_link_collision_2'>
        <pose>0 0.05 0.4436 1.5708 -0 3.14159</pose>
        <geometry>
          <mesh>
            <scale>0.001 0.001 0.001</scale>
            <uri>model://ngeeann_av/meshes/spoiler.stl</uri>
          </mesh>
        </geometry>
        <surface>
          <contact>
            <ode/>
          </contact>
          <friction>
            <ode>
              <mu>0.2</mu>
              <mu2>0.2</mu2>
            </ode>
          </friction>
        </surface>
      </collision>
      <visual name='base_link_fixed_joint_lump__chassis_link_visual'>
        <pose>0 0 0.4936 0 -0 0</pose>
        <geometry>
          <mesh>
            <scale>0.001 0.001 0.001</scale>
            <uri>model://ngeeann_av/meshes/chassis_link.stl</uri>
          </mesh>
        </geometry>
      </visual>
      <visual name='base_link_fixed_joint_lump__hokuyo_link_visual_1'>
        <pose>0 2.34 0.7336 0 -0 1.5708</pose>
        <geometry>
          <mesh>
            <scale>1 1 1</scale>
            <uri>model://ngeeann_av/meshes/hokuyo.dae</uri>
          </mesh>
        </geometry>
      </visual>
      <visual name='base_link_fixed_joint_lump__spoiler_link_visual_2'>
        <pose>0 0.05 0.4436 1.5708 -0 3.14159</pose>
        <geometry>
          <mesh>
            <scale>0.001 0.001 0.001</scale>
            <uri>model://ngeeann_av/meshes/spoiler.stl</uri>
          </mesh>
        </geometry>
        <material>
          <script>
            <name>Gazebo/DarkGrey</name>
            <uri>file://media/materials/scripts/gazebo.material</uri>
          </script>
        </material>
      </visual>
      <self_collide>1</self_collide>
      <gravity>1</gravity>
    </link>
    <joint name='bl_axle' type='revolute'>
      <pose relative_to='base_link'>-0.875 -1.01364 0.349237 0 -0 0</pose>
      <parent>base_link</parent>
      <child>bl_1</child>
      <axis>
        <xyz>-1 0 0</xyz>
        <limit>
          <lower>-1e+16</lower>
          <upper>1e+16</upper>
        </limit>
        <dynamics>
          <spring_reference>0</spring_reference>
          <spring_stiffness>0</spring_stiffness>
        </dynamics>
      </axis>
    </joint>
    <link name='bl_1'>
      <pose relative_to='bl_axle'>0 0 0 0 -0 0</pose>
      <inertial>
        <pose>0 0 0 0 -0 0</pose>
        <mass>24.5</mass>
        <inertia>
          <ixx>0.831979</ixx>
          <ixy>0</ixy>
          <ixz>0</ixz>
          <iyy>0.831979</iyy>
          <iyz>0</iyz>
          <izz>1.50063</izz>
        </inertia>
      </inertial>
      <collision name='bl_1_collision'>
        <pose>0 0 0 0 1.5708 0</pose>
        <geometry>
          <cylinder>
            <length>0.2</length>
            <radius>0.35</radius>
          </cylinder>
        </geometry>
        <surface>
          <contact>
            <ode/>
          </contact>
          <friction>
            <ode>
              <mu>1.7</mu>
              <mu2>1.7</mu2>
            </ode>
          </friction>
        </surface>
      </collision>
      <visual name='bl_1_visual'>
        <pose>0 0 0 0 1.5708 0</pose>
        <geometry>
          <cylinder>
            <length>0.2</length>
            <radius>0.35</radius>
          </cylinder>
        </geometry>
        <material>
          <script>
            <name>Gazebo/Black</name>
            <uri>file://media/materials/scripts/gazebo.material</uri>
          </script>
        </material>
      </visual>
      <self_collide>1</self_collide>
    </link>
    <joint name='br_axle' type='revolute'>
      <pose relative_to='base_link'>0.875 -1.01364 0.349237 0 -0 0</pose>
      <parent>base_link</parent>
      <child>br_1</child>
      <axis>
        <xyz>-1 0 0</xyz>
        <limit>
          <lower>-1e+16</lower>
          <upper>1e+16</upper>
        </limit>
        <dynamics>
          <spring_reference>0</spring_reference>
          <spring_stiffness>0</spring_stiffness>
        </dynamics>
      </axis>
    </joint>
    <link name='br_1'>
      <pose relative_to='br_axle'>0 0 0 0 -0 0</pose>
      <inertial>
        <pose>0 0 0 0 -0 0</pose>
        <mass>24.5</mass>
        <inertia>
          <ixx>0.831979</ixx>
          <ixy>0</ixy>
          <ixz>0</ixz>
          <iyy>0.831979</iyy>
          <iyz>0</iyz>
          <izz>1.50063</izz>
        </inertia>
      </inertial>
      <collision name='br_1_collision'>
        <pose>0 0 0 0 1.5708 0</pose>
        <geometry>
          <cylinder>
            <length>0.2</length>
            <radius>0.35</radius>
          </cylinder>
        </geometry>
        <surface>
          <contact>
            <ode/>
          </contact>
          <friction>
            <ode>
              <mu>1.7</mu>
              <mu2>1.7</mu2>
            </ode>
          </friction>
        </surface>
      </collision>
      <visual name='br_1_visual'>
        <pose>0 0 0 0 1.5708 0</pose>
        <geometry>
          <cylinder>
            <length>0.2</length>
            <radius>0.35</radius>
          </cylinder>
        </geometry>
        <material>
          <script>
            <name>Gazebo/Black</name>
            <uri>file://media/materials/scripts/gazebo.material</uri>
          </script>
        </material>
      </visual>
      <self_collide>1</self_collide>
    </link>
    <joint name='l_steer' type='revolute'>
      <pose relative_to='base_link'>-0.825 1.51736 0.349237 0 -0 0</pose>
      <parent>base_link</parent>
      <child>l_steer_1</child>
      <axis>
        <xyz>0 0 1</xyz>
        <limit>
          <lower>-0.95</lower>
          <upper>0.95</upper>
          <effort>1000</effort>
          <velocity>100</velocity>
        </limit>
        <dynamics>
          <damping>0.01</damping>
          <friction>0.01</friction>
          <spring_reference>0</spring_reference>
          <spring_stiffness>0</spring_stiffness>
        </dynamics>
      </axis>
    </joint>
    <link name='l_steer_1'>
      <pose relative_to='l_steer'>0 0 0 0 -0 0</pose>
      <inertial>
        <pose>0.003381 0 0.02162 0 -0 0</pose>
        <mass>1</mass>
        <inertia>
          <ixx>1</ixx>
          <ixy>0</ixy>
          <ixz>0</ixz>
          <iyy>1</iyy>
          <iyz>0</iyz>
          <izz>1</izz>
        </inertia>
      </inertial>
      <self_collide>1</self_collide>
    </link>
    <joint name='fl_axle' type='revolute'>
      <pose relative_to='l_steer_1'>0.05 0 0 0 -0 0</pose>
      <parent>l_steer_1</parent>
      <child>fl_1</child>
      <axis>
        <xyz>-1 0 0</xyz>
        <limit>
          <lower>-1e+16</lower>
          <upper>1e+16</upper>
        </limit>
        <dynamics>
          <spring_reference>0</spring_reference>
          <spring_stiffness>0</spring_stiffness>
        </dynamics>
      </axis>
    </joint>
    <link name='fl_1'>
      <pose relative_to='fl_axle'>0 0 0 0 -0 0</pose>
      <inertial>
        <pose>0 0 0 0 -0 0</pose>
        <mass>24.5</mass>
        <inertia>
          <ixx>0.831979</ixx>
          <ixy>0</ixy>
          <ixz>0</ixz>
          <iyy>0.831979</iyy>
          <iyz>0</iyz>
          <izz>1.50063</izz>
        </inertia>
      </inertial>
      <collision name='fl_1_collision'>
        <pose>0 0 0 0 1.5708 0</pose>
        <geometry>
          <cylinder>
            <length>0.2</length>
            <radius>0.35</radius>
          </cylinder>
        </geometry>
        <surface>
          <contact>
            <ode/>
          </contact>
          <friction>
            <ode>
              <mu>1.7</mu>
              <mu2>1.7</mu2>
            </ode>
          </friction>
        </surface>
      </collision>
      <visual name='fl_1_visual'>
        <pose>0 0 0 0 1.5708 0</pose>
        <geometry>
          <cylinder>
            <length>0.2</length>
            <radius>0.35</radius>
          </cylinder>
        </geometry>
        <material>
          <script>
            <name>Gazebo/DarkGrey</name>
            <uri>file://media/materials/scripts/gazebo.material</uri>
          </script>
        </material>
      </visual>
      <self_collide>1</self_collide>
    </link>
    <joint name='r_steer' type='revolute'>
      <pose relative_to='base_link'>0.825 1.51736 0.349237 0 -0 0</pose>
      <parent>base_link</parent>
      <child>r_steer_1</child>
      <axis>
        <xyz>0 0 1</xyz>
        <limit>
          <lower>-0.95</lower>
          <upper>0.95</upper>
          <effort>1000</effort>
          <velocity>100</velocity>
        </limit>
        <dynamics>
          <damping>0.01</damping>
          <friction>0.01</friction>
          <spring_reference>0</spring_reference>
          <spring_stiffness>0</spring_stiffness>
        </dynamics>
      </axis>
    </joint>
    <link name='r_steer_1'>
      <pose relative_to='r_steer'>0 0 0 0 -0 0</pose>
      <inertial>
        <pose>0.003381 0 0.02162 0 -0 0</pose>
        <mass>1</mass>
        <inertia>
          <ixx>1</ixx>
          <ixy>0</ixy>
          <ixz>0</ixz>
          <iyy>1</iyy>
          <iyz>0</iyz>
          <izz>1</izz>
        </inertia>
      </inertial>
      <self_collide>1</self_collide>
    </link>
    <joint name='fr_axle' type='revolute'>
      <pose relative_to='r_steer_1'>0.05 0 0 0 -0 0</pose>
      <parent>r_steer_1</parent>
      <child>fr_1</child>
      <axis>
        <xyz>-1 0 0</xyz>
        <limit>
          <lower>-1e+16</lower>
          <upper>1e+16</upper>
        </limit>
        <dynamics>
          <spring_reference>0</spring_reference>
          <spring_stiffness>0</spring_stiffness>
        </dynamics>
      </axis>
    </joint>
    <link name='fr_1'>
      <pose relative_to='fr_axle'>0 0 0 0 -0 0</pose>
      <inertial>
        <pose>0 0 0 0 -0 0</pose>
        <mass>24.5</mass>
        <inertia>
          <ixx>0.831979</ixx>
          <ixy>0</ixy>
          <ixz>0</ixz>
          <iyy>0.831979</iyy>
          <iyz>0</iyz>
          <izz>1.50063</izz>
        </inertia>
      </inertial>
      <collision name='fr_1_collision'>
        <pose>0 0 0 0 1.5708 0</pose>
        <geometry>
          <cylinder>
            <length>0.2</length>
            <radius>0.35</radius>
          </cylinder>
        </geometry>
        <surface>
          <contact>
            <ode/>
          </contact>
          <friction>
            <ode>
              <mu>1.7</mu>
              <mu2>1.7</mu2>
            </ode>
          </friction>
        </surface>
      </collision>
      <visual name='fr_1_visual'>
        <pose>0 0 0 0 1.5708 0</pose>
        <geometry>
          <cylinder>
            <length>0.2</length>
            <radius>0.35</radius>
          </cylinder>
        </geometry>
        <material>
          <script>
            <name>Gazebo/DarkGrey</name>
            <uri>file://media/materials/scripts/gazebo.material</uri>
          </script>
        </material>
      </visual>
      <self_collide>1</self_collide>
    </link>
  </model>
</sdf>
